<?xml version="1.0" ?>
<!-- =================================================================================== -->
<!-- |    This document was autogenerated by xacro from all_components.urdf.xacro      | -->
<!-- |    EDITING THIS FILE BY HAND IS NOT RECOMMENDED                                 | -->
<!-- =================================================================================== -->
<!-- All components of ROS-TMS project -->
<robot name="ros-tms" xmlns:controller="http://playerstage.sourceforge.net/gazebo/xmlschema/#controller" xmlns:interface="http://playerstage.sourceforge.net/gazebo/xmlschema/#interface" xmlns:sensor="http://playerstage.sourceforge.net/gazebo/xmlschema/#sensor" xmlns:xacro="http://www.ros.org/wiki/xacro">
  <!-- Import common properties -->
  <!-- Used for fixing all components to 'world' frame of RViz and Gazebo 'world' -->
  <link name="world_link"/>
  <joint name="world_bsen_room_joint" type="fixed">
    <parent link="world_link"/>
    <child link="bsen_room_link"/>
    <origin rpy="0 0 0" xyz="0 0 0"/>
  </joint>
  <joint name="world_smartpal5_joint" type="fixed">
    <parent link="world_link"/>
    <child link="smartpal5_link"/>
    <origin rpy="0 0 0" xyz="0 0 0"/>
  </joint>
  <!-- Defines the components tags -->
  <!-- Import all Gazebo-customization elements, including Gazebo colors -->
  <!--  Environment -->
  <link name="bsen_room_link">
    <visual>
      <geometry>
        <mesh filename="package://environmental_model/model/bsen.dae"/>
      </geometry>
      <origin rpy="0 0 0" xyz="0 0 0.001"/>
    </visual>
    <inertial>
      <origin rpy="0 0 0" xyz="0 0 0.001"/>
      <mass value="1"/>
      <inertia ixx="1.0" ixy="0.0" ixz="0.0" iyy="1.0" iyz="0.0" izz="1.0"/>
    </inertial>
  </link>
  <joint name="wall_joint" type="fixed">
    <parent link="bsen_room_link"/>
    <child link="bsen_wall_link"/>
    <origin rpy="0 0 0" xyz="0. 0. 0."/>
  </joint>
  <link name="bsen_wall_link">
    <visual>
      <geometry>
        <mesh filename="package://environmental_model/model/bsen_wall.dae"/>
      </geometry>
    </visual>
  </link>
  <joint name="celling_joint" type="fixed">
    <parent link="bsen_room_link"/>
    <child link="bsen_celling_link"/>
    <origin rpy="0 0 0" xyz="0. 0. 2.3"/>
  </joint>
  <link name="bsen_celling_link">
    <visual>
      <geometry>
        <mesh filename="package://environmental_model/model/bsen_celling.dae"/>
      </geometry>
    </visual>
  </link>
  <joint name="kitchen_joint" type="fixed">
    <parent link="bsen_room_link"/>
    <child link="kitchen_link"/>
    <origin rpy="0 0 -1.57079633" xyz="9.26 5.9 0.4855"/>
  </joint>
  <link name="kitchen_link">
    <visual>
      <geometry>
        <mesh filename="package://environmental_model/model/kitchen.dae"/>
      </geometry>
    </visual>
  </link>
  <joint name="meeting_table_joint" type="fixed">
    <parent link="bsen_room_link"/>
    <child link="meeting_table_link"/>
    <origin rpy="0 0 0" xyz="5.7 1.5 0.36"/>
  </joint>
  <link name="meeting_table_link">
    <visual>
      <geometry>
        <mesh filename="package://environmental_model/model/meeting_table.dae"/>
      </geometry>
    </visual>
  </link>
  <joint name="tree_link" type="fixed">
    <parent link="bsen_room_link"/>
    <child link="tree_link"/>
    <origin rpy="0 0 0" xyz="14.3 5.3 0."/>
  </joint>
  <link name="tree_link">
    <visual>
      <geometry>
        <mesh filename="package://environmental_model/model/tree.dae"/>
      </geometry>
    </visual>
  </link>
  <joint name="tv_table_joint" type="fixed">
    <parent link="bsen_room_link"/>
    <child link="tv_table_link"/>
    <origin rpy="0 0 0" xyz="11.1 2.9 0.175"/>
  </joint>
  <link name="tv_table_link">
    <visual>
      <geometry>
        <mesh filename="package://environmental_model/model/tv_table.dae"/>
      </geometry>
    </visual>
  </link>
  <joint name="tv_52_link" type="fixed">
    <parent link="bsen_room_link"/>
    <child link="tv_52_link"/>
    <origin rpy="0 0 -1.57079633" xyz="11.2 2.9 0.7085"/>
  </joint>
  <link name="tv_52_link">
    <visual>
      <geometry>
        <mesh filename="package://environmental_model/model/tv_52.dae"/>
      </geometry>
    </visual>
  </link>
  <joint name="recorder_joint" type="fixed">
    <parent link="bsen_room_link"/>
    <child link="recorder_link"/>
    <origin rpy="0 0 3.14159265" xyz="11.1 2.9 0.3805"/>
  </joint>
  <link name="recorder_link">
    <visual>
      <geometry>
        <mesh filename="package://environmental_model/model/recorder.dae"/>
      </geometry>
    </visual>
  </link>
  <joint name="sofa_joint" type="fixed">
    <parent link="bsen_room_link"/>
    <child link="sofa_link"/>
    <origin rpy="0 0 0" xyz="9.1 2.9 0.395"/>
  </joint>
  <link name="sofa_link">
    <visual>
      <geometry>
        <mesh filename="package://environmental_model/model/sofa.dae"/>
      </geometry>
    </visual>
  </link>
  <joint name="sofa_table_joint" type="fixed">
    <parent link="bsen_room_link"/>
    <child link="sofa_table_link"/>
    <origin rpy="0 0 0" xyz="10.2 2.9 0.235"/>
  </joint>
  <link name="sofa_table_link">
    <visual>
      <geometry>
        <mesh filename="package://environmental_model/model/sofa_table.dae"/>
      </geometry>
    </visual>
  </link>
  <joint name="carpet_joint" type="fixed">
    <parent link="bsen_room_link"/>
    <child link="carpet_link"/>
    <origin rpy="0 0 0" xyz="9.9 2.9 0.1"/>
  </joint>
  <link name="carpet_link">
    <visual>
      <geometry>
        <mesh filename="package://environmental_model/model/carpet.dae"/>
      </geometry>
    </visual>
  </link>
  <joint name="drawer_joint" type="fixed">
    <parent link="bsen_room_link"/>
    <child link="drawer_link"/>
    <origin rpy="0 0 -1.57079633" xyz="12.93 5.8 0.303"/>
  </joint>
  <link name="drawer_link">
    <visual>
      <geometry>
        <mesh filename="package://environmental_model/model/drawer.dae"/>
      </geometry>
    </visual>
  </link>
  <joint name="bed_joint" type="fixed">
    <parent link="bsen_room_link"/>
    <child link="bed_link"/>
    <origin rpy="0 0 0" xyz="12.48 2.3 0.2075"/>
  </joint>
  <link name="bed_link">
    <visual>
      <geometry>
        <mesh filename="package://environmental_model/model/bed.dae"/>
      </geometry>
    </visual>
  </link>
  <joint name="wardrobe_joint" type="fixed">
    <parent link="bsen_room_link"/>
    <child link="wardrobe_link"/>
    <origin rpy="0 0 -1.57079633" xyz="13.7 5.9 1.3"/>
  </joint>
  <link name="wardrobe_link">
    <visual>
      <geometry>
        <mesh filename="package://environmental_model/model/wardrobe.dae"/>
      </geometry>
    </visual>
  </link>
  <joint name="workdesk_joint" type="fixed">
    <parent link="bsen_room_link"/>
    <child link="workdesk_link"/>
    <origin rpy="0 0 -1.57079633" xyz="12.05 5.9 0.5"/>
  </joint>
  <link name="workdesk_link">
    <visual>
      <geometry>
        <mesh filename="package://environmental_model/model/work_desk.dae"/>
      </geometry>
    </visual>
  </link>
  <joint name="tv_multi_joint" type="fixed">
    <parent link="bsen_room_link"/>
    <child link="tv_multi_link"/>
    <origin rpy="0 0 -1.57079633" xyz="14.37 2.2 1.0"/>
  </joint>
  <link name="tv_multi_link">
    <visual>
      <geometry>
        <mesh filename="package://environmental_model/model/tv_multi.dae"/>
      </geometry>
    </visual>
  </link>
  <joint name="intelingent_shelf_joint" type="fixed">
    <parent link="bsen_room_link"/>
    <child link="intelingent_shelf_link"/>
    <origin rpy="0 0 0" xyz="11.56 3.520 0.445"/>
  </joint>
  <link name="intelingent_shelf_link">
    <visual>
      <geometry>
        <mesh filename="package://environmental_model/model/intelingent_shelf.dae"/>
      </geometry>
    </visual>
  </link>
  <!-- Import all Gazebo-customization elements, including Gazebo colors -->
  <!-- meeting_chair -->
  <!-- chair -->
  <link name="chair_x_link"/>
  <joint name="chair_x_joint" type="prismatic">
    <parent link="world_link"/>
    <child link="chair_x_link"/>
    <origin rpy="0 0 0" xyz="0 0 0"/>
    <limit effort="1000.0" lower="0." upper="15." velocity="0.5"/>
  </joint>
  <link name="chair_y_link"/>
  <joint name="chair_y_joint" type="prismatic">
    <parent link="chair_x_link"/>
    <child link="chair_y_link"/>
    <origin rpy="0 0 1.57079633" xyz="0 0 0"/>
    <limit effort="1000.0" lower="0." upper="8." velocity="0.5"/>
  </joint>
  <joint name="chair_yaw_joint" type="continuous">
    <parent link="chair_y_link"/>
    <child link="chair"/>
    <origin rpy="0 0 0" xyz="0 0 0"/>
    <axis xyz="0 0 1"/>
  </joint>
  <link name="chair">
    <visual>
      <geometry>
        <mesh filename="package://environmental_model/model/chair.dae"/>
      </geometry>
      <origin rpy="0.0 0.0 0.0" xyz="0.0 0.0 0.51"/>
    </visual>
  </link>
  <!-- refrigerator -->
  <link name="refrigerator_x_link"/>
  <joint name="refrigerator_x_joint" type="prismatic">
    <parent link="world_link"/>
    <child link="refrigerator_x_link"/>
    <origin rpy="0 0 0" xyz="0 0 0"/>
    <limit effort="1000.0" lower="0." upper="15." velocity="0.5"/>
  </joint>
  <link name="refrigerator_y_link"/>
  <joint name="refrigerator_y_joint" type="prismatic">
    <parent link="refrigerator_x_link"/>
    <child link="refrigerator_y_link"/>
    <origin rpy="0 0 1.57079633" xyz="0 0 0"/>
    <limit effort="1000.0" lower="0." upper="8." velocity="0.5"/>
  </joint>
  <joint name="refrigerator_yaw_joint" type="continuous">
    <parent link="refrigerator_y_link"/>
    <child link="refrigerator"/>
    <origin rpy="0 0 0" xyz="0 0 0"/>
    <axis xyz="0 0 1"/>
  </joint>
  <link name="refrigerator">
    <visual>
      <geometry>
        <mesh filename="package://environmental_model/model/refrigerator.dae"/>
      </geometry>
      <origin rpy="0 0 0" xyz="0.0 0.0 0.56"/>
    </visual>
  </link>
  <!-- Add meeting_chair -->
  <link name="meeting_chair1_x_link"/>
  <joint name="meeting_chair1_x_joint" type="prismatic">
    <parent link="world_link"/>
    <child link="meeting_chair1_x_link"/>
    <origin rpy="0 0 0" xyz="0 0 0"/>
    <limit effort="1000.0" lower="0." upper="15." velocity="0.5"/>
  </joint>
  <link name="meeting_chair1_y_link"/>
  <joint name="meeting_chair1_y_joint" type="prismatic">
    <parent link="meeting_chair1_x_link"/>
    <child link="meeting_chair1_y_link"/>
    <origin rpy="0 0 1.57079633" xyz="0 0 0"/>
    <limit effort="1000.0" lower="0." upper="8." velocity="0.5"/>
  </joint>
  <joint name="meeting_chair1_yaw_joint" type="continuous">
    <parent link="meeting_chair1_y_link"/>
    <child link="meeting_chair1"/>
    <origin rpy="0 0 0" xyz="0 0 0"/>
    <axis xyz="0 0 1"/>
  </joint>
  <link name="meeting_chair1">
    <visual>
      <geometry>
        <mesh filename="package://environmental_model/model/meeting_chair.dae"/>
      </geometry>
      <origin rpy="0 0 0" xyz="0.0 0.0 0.3978"/>
    </visual>
  </link>
  <link name="meeting_chair2_x_link"/>
  <joint name="meeting_chair2_x_joint" type="prismatic">
    <parent link="world_link"/>
    <child link="meeting_chair2_x_link"/>
    <origin rpy="0 0 0" xyz="0 0 0"/>
    <limit effort="1000.0" lower="0." upper="15." velocity="0.5"/>
  </joint>
  <link name="meeting_chair2_y_link"/>
  <joint name="meeting_chair2_y_joint" type="prismatic">
    <parent link="meeting_chair2_x_link"/>
    <child link="meeting_chair2_y_link"/>
    <origin rpy="0 0 1.57079633" xyz="0 0 0"/>
    <limit effort="1000.0" lower="0." upper="8." velocity="0.5"/>
  </joint>
  <joint name="meeting_chair2_yaw_joint" type="continuous">
    <parent link="meeting_chair2_y_link"/>
    <child link="meeting_chair2"/>
    <origin rpy="0 0 0" xyz="0 0 0"/>
    <axis xyz="0 0 1"/>
  </joint>
  <link name="meeting_chair2">
    <visual>
      <geometry>
        <mesh filename="package://environmental_model/model/meeting_chair.dae"/>
      </geometry>
      <origin rpy="0 0 0" xyz="0.0 0.0 0.3978"/>
    </visual>
  </link>
  <link name="meeting_chair3_x_link"/>
  <joint name="meeting_chair3_x_joint" type="prismatic">
    <parent link="world_link"/>
    <child link="meeting_chair3_x_link"/>
    <origin rpy="0 0 0" xyz="0 0 0"/>
    <limit effort="1000.0" lower="0." upper="15." velocity="0.5"/>
  </joint>
  <link name="meeting_chair3_y_link"/>
  <joint name="meeting_chair3_y_joint" type="prismatic">
    <parent link="meeting_chair3_x_link"/>
    <child link="meeting_chair3_y_link"/>
    <origin rpy="0 0 1.57079633" xyz="0 0 0"/>
    <limit effort="1000.0" lower="0." upper="8." velocity="0.5"/>
  </joint>
  <joint name="meeting_chair3_yaw_joint" type="continuous">
    <parent link="meeting_chair3_y_link"/>
    <child link="meeting_chair3"/>
    <origin rpy="0 0 0" xyz="0 0 0"/>
    <axis xyz="0 0 1"/>
  </joint>
  <link name="meeting_chair3">
    <visual>
      <geometry>
        <mesh filename="package://environmental_model/model/meeting_chair.dae"/>
      </geometry>
      <origin rpy="0 0 0" xyz="0.0 0.0 0.3978"/>
    </visual>
  </link>
  <link name="meeting_chair4_x_link"/>
  <joint name="meeting_chair4_x_joint" type="prismatic">
    <parent link="world_link"/>
    <child link="meeting_chair4_x_link"/>
    <origin rpy="0 0 0" xyz="0 0 0"/>
    <limit effort="1000.0" lower="0." upper="15." velocity="0.5"/>
  </joint>
  <link name="meeting_chair4_y_link"/>
  <joint name="meeting_chair4_y_joint" type="prismatic">
    <parent link="meeting_chair4_x_link"/>
    <child link="meeting_chair4_y_link"/>
    <origin rpy="0 0 1.57079633" xyz="0 0 0"/>
    <limit effort="1000.0" lower="0." upper="8." velocity="0.5"/>
  </joint>
  <joint name="meeting_chair4_yaw_joint" type="continuous">
    <parent link="meeting_chair4_y_link"/>
    <child link="meeting_chair4"/>
    <origin rpy="0 0 0" xyz="0 0 0"/>
    <axis xyz="0 0 1"/>
  </joint>
  <link name="meeting_chair4">
    <visual>
      <geometry>
        <mesh filename="package://environmental_model/model/meeting_chair.dae"/>
      </geometry>
      <origin rpy="0 0 0" xyz="0.0 0.0 0.3978"/>
    </visual>
  </link>
  <!-- wagon -->
  <link name="wagon_x_link"/>
  <joint name="wagon_x_joint" type="prismatic">
    <parent link="world_link"/>
    <child link="wagon_x_link"/>
    <origin rpy="0 0 0" xyz="0 0 0"/>
    <limit effort="1000.0" lower="0." upper="15." velocity="0.5"/>
  </joint>
  <link name="wagon_y_link"/>
  <joint name="wagon_y_joint" type="prismatic">
    <parent link="wagon_x_link"/>
    <child link="wagon_y_link"/>
    <origin rpy="0 0 1.57079633" xyz="0 0 0"/>
    <limit effort="1000.0" lower="0." upper="8." velocity="0.5"/>
  </joint>
  <joint name="wagon_yaw_joint" type="continuous">
    <parent link="wagon_y_link"/>
    <child link="wagon"/>
    <origin rpy="0 0 0" xyz="0 0 0"/>
    <axis xyz="0 0 1"/>
  </joint>
  <link name="wagon">
    <visual>
      <geometry>
        <mesh filename="package://environmental_model/model/wagon.dae"/>
      </geometry>
      <origin rpy="0 0 0" xyz="0. 0. 0.5"/>
    </visual>
  </link>
  <!-- Import all Gazebo-customization elements, including Gazebo colors -->
  <!-- Base, Vehicle -->
  <link name="smartpal5_link"/>
  <joint name="smartpal5_x_joint" type="prismatic">
    <parent link="smartpal5_link"/>
    <child link="smartpal5_x_link"/>
    <origin rpy="0 0 0" xyz="0 0 0"/>
    <limit effort="1000.0" lower="-5." upper="5." velocity="0.5"/>
  </joint>
  <link name="smartpal5_x_link"/>
  <joint name="smartpal5_y_joint" type="prismatic">
    <parent link="smartpal5_x_link"/>
    <child link="smartpal5_y_link"/>
    <origin rpy="0 0 1.57075" xyz="0 0 0"/>
    <limit effort="1000.0" lower="-5." upper="5." velocity="0.5"/>
  </joint>
  <link name="smartpal5_y_link"/>
  <joint name="smartpal5_yaw_joint" type="continuous">
    <parent link="smartpal5_y_link"/>
    <child link="base_footprint"/>
    <origin rpy="0 0 -1.57075" xyz="0 0 0"/>
    <axis xyz="0 0 1"/>
  </joint>
  <link name="base_footprint"/>
  <joint name="base_footprint_joint" type="fixed">
    <parent link="base_footprint"/>
    <child link="base_link"/>
    <origin rpy="0 0 0" xyz="0 0 0"/>
  </joint>
  <link name="base_link">
    <visual>
      <geometry>
        <mesh filename="package://smartpal5_description/meshes/visual/Pal5_body_vehicle.dae"/>
      </geometry>
      <origin rpy="0 0 0" xyz="0 0 0"/>
      <!-- Offset for wheels already included in the mesh definition -->
      <material name="grey"/>
    </visual>
    <collision>
      <geometry>
        <mesh filename="package://smartpal5_description/meshes/collision/Pal5_body_vehicle.dae"/>
      </geometry>
      <origin rpy="0 0 0" xyz="0 0 0"/>
    </collision>
    <inertial>
      <origin rpy="0 0 0" xyz="0 0 0.0375"/>
      <mass value="27"/>
      <inertia ixx="1.0" ixy="0.0" ixz="0.0" iyy="1.0" iyz="0.0" izz="1.0"/>
    </inertial>
  </link>
  <!-- Lumbar -->
  <joint name="lumbar_lower_joint" type="revolute">
    <parent link="base_link"/>
    <child link="lumbar_lower_link"/>
    <origin rpy="-1.57075 0 0" xyz="0 0 0.4365"/>
    <axis xyz="0 0 1"/>
    <limit effort="100.0" lower="-0.2" upper="0.00872664625997165" velocity="1.0"/>
  </joint>
  <link name="lumbar_lower_link">
    <visual>
      <geometry>
        <mesh filename="package://smartpal5_description/meshes/visual/Pal5_body_lumbar-J1.dae"/>
      </geometry>
      <origin rpy="0 0 0" xyz="0 0 0"/>
      <material name="grey"/>
    </visual>
    <collision>
      <geometry>
        <mesh filename="package://smartpal5_description/meshes/collision/Pal5_body_lumbar-J1.dae"/>
      </geometry>
      <origin rpy="0 0 0" xyz="0 0 0"/>
    </collision>
    <inertial>
      <origin rpy="0 0 0" xyz="0 0 -0.1"/>
      <mass value="6"/>
      <inertia ixx="1.0" ixy="0.0" ixz="0.0" iyy="1.0" iyz="0.0" izz="1.0"/>
    </inertial>
  </link>
  <joint name="lumbar_upper_joint" type="revolute">
    <parent link="lumbar_lower_link"/>
    <child link="lumbar_upper_link"/>
    <origin rpy="0 0 0" xyz="0 -0.21 0"/>
    <axis xyz="0 0 1"/>
    <limit effort="100.0" lower="-0.00872664625997165" upper="2.10312174865317" velocity="1.0"/>
  </joint>
  <link name="lumbar_upper_link">
    <visual>
      <geometry>
        <mesh filename="package://smartpal5_description/meshes/visual/Pal5_body_lumbar-J2.dae"/>
      </geometry>
      <origin rpy="0 0 0" xyz="0 0 0"/>
      <material name="grey"/>
    </visual>
    <collision>
      <geometry>
        <mesh filename="package://smartpal5_description/meshes/collision/Pal5_body_lumbar-J2.dae"/>
      </geometry>
      <origin rpy="0 0 0" xyz="0 0 0"/>
    </collision>
    <inertial>
      <origin rpy="0 0 0" xyz="0.11 0 0.25"/>
      <mass value="30"/>
      <inertia ixx="1.0" ixy="0.0" ixz="0.0" iyy="1.0" iyz="0.0" izz="1.0"/>
    </inertial>
  </link>
  <!-- RGB-D Camera -->
  <joint name="head_camera_joint" type="fixed">
    <parent link="lumbar_upper_link"/>
    <child link="camera_link"/>
    <origin rpy="1.57075 0 0" xyz="0.02 -0.7 0"/>
  </joint>
  <link name="camera_link">
    <visual>
      <geometry>
        <box size="0.03 0.15 0.05"/>
      </geometry>
      <origin rpy="0 0 0" xyz="0 0 0"/>
      <material name="grey"/>
    </visual>
    <collision>
      <geometry>
        <box size="0.05 0.2 0.08"/>
      </geometry>
      <origin rpy="0 0 0" xyz="0 0 0"/>
    </collision>
    <inertial>
      <origin rpy="0 0 0" xyz="0 0 0"/>
      <mass value="0.5"/>
      <inertia ixx="1.0" ixy="0.0" ixz="0.0" iyy="1.0" iyz="0.0" izz="1.0"/>
    </inertial>
  </link>
  <!-- Left Arm -->
  <joint name="l_arm_j1_joint" type="revolute">
    <parent link="lumbar_upper_link"/>
    <child link="l_arm_j1_link"/>
    <origin rpy="3.14159 0 0" xyz="-0.025 -0.480 0.200"/>
    <axis xyz="0 0 1"/>
    <limit effort="100.0" lower="-0.7679" upper="3.1066" velocity="1.0"/>
  </joint>
  <link name="l_arm_j1_link">
    <visual>
      <geometry>
        <mesh filename="package://smartpal5_description/meshes/visual/Pal5_leftArm_J1.dae"/>
      </geometry>
      <origin rpy="0 0 0" xyz="0 0 0"/>
      <material name="grey"/>
    </visual>
    <collision>
      <geometry>
        <mesh filename="package://smartpal5_description/meshes/collision/Pal5_leftArm_J1.dae"/>
      </geometry>
      <origin rpy="0 0 0" xyz="0 0 0"/>
    </collision>
    <inertial>
      <origin rpy="0 0 0" xyz="0 0 -0.1"/>
      <mass value="0.6"/>
      <inertia ixx="1.0" ixy="0.0" ixz="0.0" iyy="1.0" iyz="0.0" izz="1.0"/>
    </inertial>
  </link>
  <joint name="l_arm_j2_joint" type="revolute">
    <parent link="l_arm_j1_link"/>
    <child link="l_arm_j2_link"/>
    <origin rpy="1.57075 3.14159 1.57075" xyz="0 0 0"/>
    <axis xyz="0 0 1"/>
    <limit effort="100.0" lower="-0.2443" upper="1.9024" velocity="1.0"/>
  </joint>
  <link name="l_arm_j2_link">
    <visual>
      <geometry>
        <mesh filename="package://smartpal5_description/meshes/visual/Pal5_leftArm_J2.dae"/>
      </geometry>
      <origin rpy="0 0 0" xyz="0 0 0"/>
      <material name="grey"/>
    </visual>
    <collision>
      <geometry>
        <mesh filename="package://smartpal5_description/meshes/collision/Pal5_leftArm_J2.dae"/>
      </geometry>
      <origin rpy="0 0 0" xyz="0 0 0"/>
    </collision>
    <inertial>
      <origin rpy="0 0 0" xyz="0 0 -0.1"/>
      <mass value="0.6"/>
      <inertia ixx="1.0" ixy="0.0" ixz="0.0" iyy="1.0" iyz="0.0" izz="1.0"/>
    </inertial>
  </link>
  <joint name="l_arm_j3_joint" type="revolute">
    <parent link="l_arm_j2_link"/>
    <child link="l_arm_j3_link"/>
    <origin rpy="1.57075 1.57075 1.57075" xyz="0 0 0"/>
    <axis xyz="0 0 1"/>
    <limit effort="100.0" lower="-2.0769" upper="2.0769" velocity="1.0"/>
  </joint>
  <link name="l_arm_j3_link">
    <visual>
      <geometry>
        <mesh filename="package://smartpal5_description/meshes/visual/Pal5_leftArm_J3.dae"/>
      </geometry>
      <origin rpy="0 0 0" xyz="0 0 0"/>
      <material name="grey"/>
    </visual>
    <collision>
      <geometry>
        <mesh filename="package://smartpal5_description/meshes/collision/Pal5_leftArm_J3.dae"/>
      </geometry>
      <origin rpy="0 0 0" xyz="0 0 0"/>
    </collision>
    <inertial>
      <origin rpy="0 0 0" xyz="0 0 0"/>
      <mass value="1"/>
      <inertia ixx="1.0" ixy="0.0" ixz="0.0" iyy="1.0" iyz="0.0" izz="1.0"/>
    </inertial>
  </link>
  <joint name="l_arm_j4_joint" type="revolute">
    <parent link="l_arm_j3_link"/>
    <child link="l_arm_j4_link"/>
    <origin rpy="-1.57075 0 3.14159" xyz="-0.02 0.0 0.25"/>
    <axis xyz="0 0 1"/>
    <limit effort="100.0" lower="-0.0174" upper="2.2514" velocity="1.0"/>
  </joint>
  <link name="l_arm_j4_link">
    <visual>
      <geometry>
        <mesh filename="package://smartpal5_description/meshes/visual/Pal5_leftArm_J4.dae"/>
      </geometry>
      <origin rpy="0 0 0" xyz="0 0 0"/>
      <material name="grey"/>
    </visual>
    <collision>
      <geometry>
        <mesh filename="package://smartpal5_description/meshes/collision/Pal5_leftArm_J4.dae"/>
      </geometry>
      <origin rpy="0 0 0" xyz="0 0 0"/>
    </collision>
    <inertial>
      <origin rpy="0 0 0" xyz="0 0 -0.3"/>
      <mass value="0.6"/>
      <inertia ixx="1.0" ixy="0.0" ixz="0.0" iyy="1.0" iyz="0.0" izz="1.0"/>
    </inertial>
  </link>
  <joint name="l_arm_j5_joint" type="revolute">
    <parent link="l_arm_j4_link"/>
    <child link="l_arm_j5_link"/>
    <origin rpy="1.57075 0 0" xyz="-0.02 0.0 0.0"/>
    <axis xyz="0 0 1"/>
    <limit effort="100.0" lower="-2.0769" upper="2.0769" velocity="1.0"/>
  </joint>
  <link name="l_arm_j5_link">
    <visual>
      <geometry>
        <mesh filename="package://smartpal5_description/meshes/visual/Pal5_leftArm_J5.dae"/>
      </geometry>
      <origin rpy="0 0 0" xyz="0 0 0"/>
      <material name="grey"/>
    </visual>
    <collision>
      <geometry>
        <mesh filename="package://smartpal5_description/meshes/collision/Pal5_leftArm_J5.dae"/>
      </geometry>
      <origin rpy="0 0 0" xyz="0 0 0"/>
    </collision>
    <inertial>
      <origin rpy="0 0 0" xyz="0 0 0.1"/>
      <mass value="0.4"/>
      <inertia ixx="1.0" ixy="0.0" ixz="0.0" iyy="1.0" iyz="0.0" izz="1.0"/>
    </inertial>
  </link>
  <joint name="l_arm_j6_joint" type="revolute">
    <parent link="l_arm_j5_link"/>
    <child link="l_arm_j6_link"/>
    <origin rpy="-1.57075 1.57075 0" xyz="0.0 0.0 0.28"/>
    <axis xyz="0 0 1"/>
    <limit effort="100.0" lower="-0.2617" upper="0.7504" velocity="1.0"/>
  </joint>
  <link name="l_arm_j6_link">
    <visual>
      <geometry>
        <mesh filename="package://smartpal5_description/meshes/visual/Pal5_leftArm_J6.dae"/>
      </geometry>
      <origin rpy="0 0 0" xyz="0 0 0"/>
      <material name="grey"/>
    </visual>
    <collision>
      <geometry>
        <mesh filename="package://smartpal5_description/meshes/collision/Pal5_leftArm_J6.dae"/>
      </geometry>
      <origin rpy="0 0 0" xyz="0 0 0"/>
    </collision>
    <inertial>
      <origin rpy="0 0 0" xyz="-0.1 0 0"/>
      <mass value="0.4"/>
      <inertia ixx="1.0" ixy="0.0" ixz="0.0" iyy="1.0" iyz="0.0" izz="1.0"/>
    </inertial>
  </link>
  <joint name="l_arm_j7_joint" type="revolute">
    <parent link="l_arm_j6_link"/>
    <child link="l_arm_j7_link"/>
    <origin rpy="1.57075 3.14159 0" xyz="0.0 0.0 0"/>
    <axis xyz="0 0 1"/>
    <limit effort="100.0" lower="0" upper="0.5" velocity="1.0"/>
  </joint>
  <link name="l_arm_j7_link">
    <visual>
      <geometry>
        <mesh filename="package://smartpal5_description/meshes/visual/Pal5_leftArm_J7.dae"/>
      </geometry>
      <origin rpy="0 0 0" xyz="0 0 0"/>
      <material name="grey"/>
    </visual>
    <collision>
      <geometry>
        <mesh filename="package://smartpal5_description/meshes/collision/Pal5_leftArm_J7.dae"/>
      </geometry>
      <origin rpy="0 0 0" xyz="0 0 0"/>
    </collision>
    <inertial>
      <origin rpy="0 0 0" xyz="0 0 -0.1"/>
      <mass value="0.4"/>
      <inertia ixx="1.0" ixy="0.0" ixz="0.0" iyy="1.0" iyz="0.0" izz="1.0"/>
    </inertial>
  </link>
  <!-- Left Gripper -->
  <joint name="l_gripper_joint" type="fixed">
    <parent link="l_arm_j7_link"/>
    <child link="l_gripper_link"/>
    <origin rpy="3.14159 3.14159 1.57075" xyz="0.056 0 0"/>
    <axis xyz="0 0 1"/>
  </joint>
  <link name="l_gripper_link">
    <visual>
      <geometry>
        <mesh filename="package://smartpal5_description/meshes/visual/Pal5_leftGripper_gripper.dae"/>
      </geometry>
      <origin rpy="0 0 0" xyz="0 0 0"/>
      <material name="grey"/>
    </visual>
    <collision>
      <geometry>
        <mesh filename="package://smartpal5_description/meshes/collision/Pal5_leftGripper_gripper.dae"/>
      </geometry>
      <origin rpy="0 0 0" xyz="0 0 0"/>
    </collision>
    <inertial>
      <origin rpy="0 0 0" xyz="0 0 -0.1"/>
      <mass value="0.6"/>
      <inertia ixx="1.0" ixy="0.0" ixz="0.0" iyy="1.0" iyz="0.0" izz="1.0"/>
    </inertial>
  </link>
  <joint name="l_end_effector_joint" type="fixed">
    <origin rpy="0 0 0" xyz="0.05 0 0"/>
    <parent link="l_gripper_link"/>
    <child link="l_end_effector_link"/>
  </joint>
  <link name="l_end_effector_link">
    <visual>
      <origin rpy="0 0 0" xyz="0 0 0"/>
      <geometry>
        <box size="0.001 0.001 0.001"/>
      </geometry>
    </visual>
    <collision>
      <origin rpy="0 0 0" xyz="0 0 0"/>
      <geometry>
        <box size="0.001 0.001 0.001"/>
      </geometry>
    </collision>
  </link>
  <joint name="l_gripper_thumb_joint" type="revolute">
    <parent link="l_gripper_link"/>
    <child link="l_gripper_thumb_link"/>
    <origin rpy="0 0 0" xyz="0.027 0.042 0.0"/>
    <axis xyz="0 0 1"/>
    <limit effort="100.0" lower="-1.0122" upper="0.1396" velocity="1.0"/>
  </joint>
  <link name="l_gripper_thumb_link">
    <visual>
      <geometry>
        <mesh filename="package://smartpal5_description/meshes/visual/Pal5_leftGripper_g-thumb.dae"/>
      </geometry>
      <origin rpy="0 0 0" xyz="0 0 0"/>
      <material name="grey"/>
    </visual>
    <collision>
      <geometry>
        <mesh filename="package://smartpal5_description/meshes/collision/Pal5_leftGripper_g-thumb.dae"/>
      </geometry>
      <origin rpy="0 0 0" xyz="0 0 0"/>
    </collision>
    <inertial>
      <origin rpy="0 0 0" xyz="0 0 -0.1"/>
      <mass value="0.4"/>
      <inertia ixx="1.0" ixy="0.0" ixz="0.0" iyy="1.0" iyz="0.0" izz="1.0"/>
    </inertial>
  </link>
  <!-- Right Arm -->
  <joint name="r_arm_j1_joint" type="revolute">
    <parent link="lumbar_upper_link"/>
    <child link="r_arm_j1_link"/>
    <origin rpy="3.14159 0 0" xyz="-0.025 -0.480 -0.200"/>
    <axis xyz="0 0 1"/>
    <limit effort="100.0" lower="-0.7679" upper="3.1066" velocity="1.0"/>
  </joint>
  <link name="r_arm_j1_link">
    <visual>
      <geometry>
        <mesh filename="package://smartpal5_description/meshes/visual/Pal5_rightArm_J1.dae"/>
      </geometry>
      <origin rpy="0 0 0" xyz="0 0 0"/>
      <material name="grey"/>
    </visual>
    <collision>
      <geometry>
        <mesh filename="package://smartpal5_description/meshes/collision/Pal5_rightArm_J1.dae"/>
      </geometry>
      <origin rpy="0 0 0" xyz="0 0 0"/>
    </collision>
    <inertial>
      <origin rpy="0 0 0" xyz="0 0 -0.1"/>
      <mass value="0.6"/>
      <inertia ixx="1.0" ixy="0.0" ixz="0.0" iyy="1.0" iyz="0.0" izz="1.0"/>
    </inertial>
  </link>
  <joint name="r_armj2_joint" type="revolute">
    <parent link="r_arm_j1_link"/>
    <child link="r_arm_j2_link"/>
    <origin rpy="-1.57075 0 -1.57075" xyz="0 0 0"/>
    <axis xyz="0 0 1"/>
    <limit effort="100.0" lower="-1.9024" upper="0.2443" velocity="1.0"/>
  </joint>
  <link name="r_arm_j2_link">
    <visual>
      <geometry>
        <mesh filename="package://smartpal5_description/meshes/visual/Pal5_rightArm_J2.dae"/>
      </geometry>
      <origin rpy="0 0 0" xyz="0 0 0"/>
      <material name="grey"/>
    </visual>
    <collision>
      <geometry>
        <mesh filename="package://smartpal5_description/meshes/collision/Pal5_rightArm_J2.dae"/>
      </geometry>
      <origin rpy="0 0 0" xyz="0 0 0"/>
    </collision>
    <inertial>
      <origin rpy="0 0 0" xyz="0 0 -0.1"/>
      <mass value="0.6"/>
      <inertia ixx="1.0" ixy="0.0" ixz="0.0" iyy="1.0" iyz="0.0" izz="1.0"/>
    </inertial>
  </link>
  <joint name="r_arm_j3_joint" type="revolute">
    <parent link="r_arm_j2_link"/>
    <child link="r_arm_j3_link"/>
    <origin rpy="1.57075 1.57075 1.57075" xyz="0 0 0"/>
    <axis xyz="0 0 1"/>
    <limit effort="100.0" lower="-2.0769" upper="2.0769" velocity="1.0"/>
  </joint>
  <link name="r_arm_j3_link">
    <visual>
      <geometry>
        <mesh filename="package://smartpal5_description/meshes/visual/Pal5_rightArm_J3.dae"/>
      </geometry>
      <origin rpy="0 0 0" xyz="0 0 0"/>
      <material name="grey"/>
    </visual>
    <collision>
      <geometry>
        <mesh filename="package://smartpal5_description/meshes/collision/Pal5_rightArm_J3.dae"/>
      </geometry>
      <origin rpy="0 0 0" xyz="0 0 0"/>
    </collision>
    <inertial>
      <origin rpy="0 0 0" xyz="0 0 0"/>
      <mass value="1"/>
      <inertia ixx="1.0" ixy="0.0" ixz="0.0" iyy="1.0" iyz="0.0" izz="1.0"/>
    </inertial>
  </link>
  <joint name="r_arm_j4_joint" type="revolute">
    <parent link="r_arm_j3_link"/>
    <child link="r_arm_j4_link"/>
    <origin rpy="-1.57075 0 3.14159" xyz="-0.02 0.0 0.25"/>
    <axis xyz="0 0 1"/>
    <limit effort="100.0" lower="-0.0174" upper="2.2514" velocity="1.0"/>
  </joint>
  <link name="r_arm_j4_link">
    <visual>
      <geometry>
        <mesh filename="package://smartpal5_description/meshes/visual/Pal5_rightArm_J4.dae"/>
      </geometry>
      <origin rpy="0 0 0" xyz="0 0 0"/>
      <material name="grey"/>
    </visual>
    <collision>
      <geometry>
        <mesh filename="package://smartpal5_description/meshes/collision/Pal5_rightArm_J4.dae"/>
      </geometry>
      <origin rpy="0 0 0" xyz="0 0 0"/>
    </collision>
    <inertial>
      <origin rpy="0 0 0" xyz="0 0 -0.3"/>
      <mass value="0.6"/>
      <inertia ixx="1.0" ixy="0.0" ixz="0.0" iyy="1.0" iyz="0.0" izz="1.0"/>
    </inertial>
  </link>
  <joint name="r_arm_j5_joint" type="revolute">
    <parent link="r_arm_j4_link"/>
    <child link="r_arm_j5_link"/>
    <origin rpy="1.57075 0 0" xyz="-0.02 0.0 0.0"/>
    <axis xyz="0 0 1"/>
    <limit effort="100.0" lower="-2.0769" upper="2.0769" velocity="1.0"/>
  </joint>
  <link name="r_arm_j5_link">
    <visual>
      <geometry>
        <mesh filename="package://smartpal5_description/meshes/visual/Pal5_rightArm_J5.dae"/>
      </geometry>
      <origin rpy="0 0 0" xyz="0 0 0"/>
      <material name="grey"/>
    </visual>
    <collision>
      <geometry>
        <mesh filename="package://smartpal5_description/meshes/collision/Pal5_rightArm_J5.dae"/>
      </geometry>
      <origin rpy="0 0 0" xyz="0 0 0"/>
    </collision>
    <inertial>
      <origin rpy="0 0 0" xyz="0 0 0.1"/>
      <mass value="0.4"/>
      <inertia ixx="1.0" ixy="0.0" ixz="0.0" iyy="1.0" iyz="0.0" izz="1.0"/>
    </inertial>
  </link>
  <joint name="r_arm_j6_joint" type="revolute">
    <parent link="r_arm_j5_link"/>
    <child link="r_arm_j6_link"/>
    <origin rpy="-1.57075 1.57075 0" xyz="0.0 0.0 0.28"/>
    <axis xyz="0 0 1"/>
    <limit effort="100.0" lower="-0.2617" upper="0.7504" velocity="1.0"/>
  </joint>
  <link name="r_arm_j6_link">
    <visual>
      <geometry>
        <mesh filename="package://smartpal5_description/meshes/visual/Pal5_rightArm_J6.dae"/>
      </geometry>
      <origin rpy="0 0 0" xyz="0 0 0"/>
      <material name="grey"/>
    </visual>
    <collision>
      <geometry>
        <mesh filename="package://smartpal5_description/meshes/collision/Pal5_rightArm_J6.dae"/>
      </geometry>
      <origin rpy="0 0 0" xyz="0 0 0"/>
    </collision>
    <inertial>
      <origin rpy="0 0 0" xyz="-0.1 0 0"/>
      <mass value="0.4"/>
      <inertia ixx="1.0" ixy="0.0" ixz="0.0" iyy="1.0" iyz="0.0" izz="1.0"/>
    </inertial>
  </link>
  <joint name="r_arm_j7_joint" type="revolute">
    <parent link="r_arm_j6_link"/>
    <child link="r_arm_j7_link"/>
    <origin rpy="1.57075 3.14159 0" xyz="0.0 0.0 0"/>
    <axis xyz="0 0 1"/>
    <limit effort="100.0" lower="-1.0122" upper="1.0" velocity="1.0"/>
  </joint>
  <link name="r_arm_j7_link">
    <visual>
      <geometry>
        <mesh filename="package://smartpal5_description/meshes/visual/Pal5_rightArm_J7.dae"/>
      </geometry>
      <origin rpy="0 0 0" xyz="0 0 0"/>
      <material name="grey"/>
    </visual>
    <collision>
      <geometry>
        <mesh filename="package://smartpal5_description/meshes/collision/Pal5_rightArm_J7.dae"/>
      </geometry>
      <origin rpy="0 0 0" xyz="0 0 0"/>
    </collision>
    <inertial>
      <origin rpy="0 0 0" xyz="0 0 -0.1"/>
      <mass value="0.4"/>
      <inertia ixx="1.0" ixy="0.0" ixz="0.0" iyy="1.0" iyz="0.0" izz="1.0"/>
    </inertial>
  </link>
  <!-- Right Gripper -->
  <joint name="r_gripper_joint" type="fixed">
    <parent link="r_arm_j7_link"/>
    <child link="r_gripper_link"/>
    <origin rpy="3.14159 3.14159 3.14159" xyz="0.056 0 0"/>
    <axis xyz="0 0 1"/>
  </joint>
  <link name="r_gripper_link">
    <visual>
      <geometry>
        <mesh filename="package://smartpal5_description/meshes/visual/Pal5_rightGripper_gripper.dae"/>
      </geometry>
      <origin rpy="0 0 0" xyz="0 0 0"/>
      <material name="grey"/>
    </visual>
    <collision>
      <geometry>
        <mesh filename="package://smartpal5_description/meshes/collision/Pal5_rightGripper_gripper.dae"/>
      </geometry>
      <origin rpy="0 0 0" xyz="0 0 0"/>
    </collision>
    <inertial>
      <origin rpy="0 0 0" xyz="0 0 -0.1"/>
      <mass value="0.6"/>
      <inertia ixx="1.0" ixy="0.0" ixz="0.0" iyy="1.0" iyz="0.0" izz="1.0"/>
    </inertial>
  </link>
  <joint name="r_end_effector_joint" type="fixed">
    <origin rpy="0 0 0" xyz="0 0.05 0"/>
    <parent link="r_gripper_link"/>
    <child link="r_end_effector_link"/>
  </joint>
  <link name="r_end_effector_link">
    <visual>
      <origin rpy="0 0 0" xyz="0 0 0"/>
      <geometry>
        <box size="0.001 0.001 0.001"/>
      </geometry>
    </visual>
    <collision>
      <origin rpy="0 0 0" xyz="0 0 0"/>
      <geometry>
        <box size="0.001 0.001 0.001"/>
      </geometry>
    </collision>
  </link>
  <joint name="r_gripper_thumb_joint" type="revolute">
    <parent link="r_gripper_link"/>
    <child link="r_gripper_thumb_link"/>
    <origin rpy="0 0 -1.57075" xyz="0.042 0.027 0.0"/>
    <axis xyz="0 0 1"/>
    <limit effort="100.0" lower="-0.1396" upper="1.0122" velocity="1.0"/>
  </joint>
  <link name="r_gripper_thumb_link">
    <visual>
      <geometry>
        <mesh filename="package://smartpal5_description/meshes/visual/Pal5_rightGripper_g-thumb.dae"/>
      </geometry>
      <origin rpy="0 0 0" xyz="0 0 0"/>
      <material name="grey"/>
    </visual>
    <collision>
      <geometry>
        <mesh filename="package://smartpal5_description/meshes/collision/Pal5_rightGripper_g-thumb.dae"/>
      </geometry>
      <origin rpy="0 0 0" xyz="0 0 0"/>
    </collision>
    <inertial>
      <origin rpy="0 0 0" xyz="0 0 -0.1"/>
      <mass value="0.4"/>
      <inertia ixx="1.0" ixy="0.0" ixz="0.0" iyy="1.0" iyz="0.0" izz="1.0"/>
    </inertial>
  </link>
</robot>

