<?xml version="1.0" ?>
<!-- =================================================================================== -->
<!-- |    This document was autogenerated by xacro from all_components_with_moveit.urdf.xacro | -->
<!-- |    EDITING THIS FILE BY HAND IS NOT RECOMMENDED                                 | -->
<!-- =================================================================================== -->
<!-- All components of ROS-TMS project -->
<robot name="rostms" xmlns:controller="http://playerstage.sourceforge.net/gazebo/xmlschema/#controller" xmlns:interface="http://playerstage.sourceforge.net/gazebo/xmlschema/#interface" xmlns:sensor="http://playerstage.sourceforge.net/gazebo/xmlschema/#sensor" xmlns:xacro="http://ros.org/wiki/xacro">
  <!-- Used for fixing all components to 'world' frame of RViz and Gazebo 'world' -->
  <link name="world_link"/>
  <joint name="world_bsen_room_joint" type="fixed">
    <parent link="world_link"/>
    <child link="bsen_room_link"/>
    <origin rpy="0 0 0" xyz="0 0 0"/>
  </joint>
  <joint name="world_smartpal5_joint" type="fixed">
    <parent link="world_link"/>
    <child link="smartpal5_link"/>
    <origin rpy="0 0 0" xyz="0 0 0"/>
  </joint>
  <!--  Environment -->
  <link name="bsen_room_link">
    <visual>
      <geometry>
        <mesh filename="package://environmental_model/model/bsen.dae"/>
      </geometry>
      <origin rpy="0 0 0" xyz="0 0 0.001"/>
    </visual>
    <collision>
      <geometry>
        <box size="15.0 7.0 0.001"/>
      </geometry>
      <origin rpy="0 0 0" xyz="7.5 3.5 -0.001"/>
    </collision>
    <inertial>
      <origin rpy="0 0 0" xyz="0 0 0.001"/>
      <mass value="100"/>
      <inertia ixx="1.0" ixy="0.0" ixz="0.0" iyy="1.0" iyz="0.0" izz="1.0"/>
    </inertial>
  </link>
  <joint name="wall_joint" type="fixed">
    <parent link="bsen_room_link"/>
    <child link="bsen_wall_link"/>
    <origin rpy="0 0 0" xyz="0. 0. 0."/>
  </joint>
  <link name="bsen_wall_link">
    <visual>
      <geometry>
        <mesh filename="package://environmental_model/model/bsen_wall.dae"/>
      </geometry>
    </visual>
    <collision>
      <geometry>
        <mesh filename="package://environmental_model/model/bsen_wall.dae"/>
      </geometry>
    </collision>
  </link>
  <joint name="celling_joint" type="fixed">
    <parent link="bsen_room_link"/>
    <child link="bsen_celling_link"/>
    <origin rpy="0 0 0" xyz="0. 0. 2.3"/>
  </joint>
  <link name="bsen_celling_link">
    <visual>
      <geometry>
        <mesh filename="package://environmental_model/model/bsen_celling.dae"/>
      </geometry>
    </visual>
    <collision>
      <geometry>
        <mesh filename="package://environmental_model/model/bsen_celling.dae"/>
      </geometry>
    </collision>
  </link>
  <joint name="kitchen_joint" type="fixed">
    <parent link="bsen_room_link"/>
    <child link="kitchen_link"/>
    <origin rpy="0 0 -1.57079633" xyz="9.03 5.87 0.4855"/>
  </joint>
  <link name="kitchen_link">
    <visual>
      <geometry>
        <mesh filename="package://environmental_model/model/kitchen.dae"/>
      </geometry>
    </visual>
    <collision>
      <geometry>
        <box size="0.65 3.12 0.65"/>
      </geometry>
    </collision>
    <inertial>
      <origin rpy="0 0 0" xyz="0 0 0.001"/>
      <mass value="50"/>
      <inertia ixx="1.0" ixy="0.0" ixz="0.0" iyy="1.0" iyz="0.0" izz="1.0"/>
    </inertial>
  </link>
  <joint name="meeting_table_joint" type="fixed">
    <parent link="bsen_room_link"/>
    <child link="meeting_table_link"/>
    <origin rpy="0 0 0" xyz="5.7 1.5 0.36"/>
  </joint>
  <link name="meeting_table_link">
    <visual>
      <geometry>
        <mesh filename="package://environmental_model/model/meeting_table.dae"/>
      </geometry>
    </visual>
    <collision>
      <geometry>
        <cylinder length="0.73" radius="0.66"/>
      </geometry>
    </collision>
  </link>
  <joint name="tree_link" type="fixed">
    <parent link="bsen_room_link"/>
    <child link="tree_link"/>
    <origin rpy="0 0 0" xyz="14.3 5.3 0."/>
  </joint>
  <link name="tree_link">
    <visual>
      <geometry>
        <mesh filename="package://environmental_model/model/tree.dae"/>
      </geometry>
    </visual>
    <collision>
      <geometry>
        <cylinder length="1.0" radius="0.2"/>
      </geometry>
      <origin rpy="0 0 0" xyz="0.0 0.0 0.55"/>
    </collision>
  </link>
  <joint name="tv_table_joint" type="fixed">
    <parent link="bsen_room_link"/>
    <child link="tv_table_link"/>
    <origin rpy="0 0 0" xyz="14.25 2.5 0.175"/>
  </joint>
  <link name="tv_table_link">
    <visual>
      <geometry>
        <mesh filename="package://environmental_model/model/tv_table.dae"/>
      </geometry>
    </visual>
    <collision>
      <geometry>
        <box size="0.35 2.7 0.35"/>
      </geometry>
    </collision>
  </link>
  <joint name="sofa_joint" type="fixed">
    <parent link="bsen_room_link"/>
    <child link="sofa_link"/>
    <origin rpy="0 0 0" xyz="11.75 2.6 0.395"/>
  </joint>
  <link name="sofa_link">
    <visual>
      <geometry>
        <mesh filename="package://environmental_model/model/sofa.dae"/>
      </geometry>
    </visual>
    <collision>
      <geometry>
        <box size="0.8 2.35 0.77"/>
      </geometry>
    </collision>
  </link>
  <joint name="sofa_table_joint" type="fixed">
    <parent link="bsen_room_link"/>
    <child link="sofa_table_link"/>
    <origin rpy="0 0 0" xyz="12.7 2.5 0.235"/>
  </joint>
  <link name="sofa_table_link">
    <visual>
      <geometry>
        <mesh filename="package://environmental_model/model/sofa_table.dae"/>
      </geometry>
    </visual>
    <collision>
      <geometry>
        <box size="0.5 1.3 0.43"/>
      </geometry>
    </collision>
  </link>
  <joint name="bed_joint" type="fixed">
    <parent link="bsen_room_link"/>
    <child link="bed_link"/>
    <origin rpy="0 0 0" xyz="10.35 2.7 0.235"/>
  </joint>
  <link name="bed_link">
    <visual>
      <geometry>
        <mesh filename="package://environmental_model/model/paramount_bed.dae"/>
      </geometry>
    </visual>
    <collision>
      <geometry>
        <box size="1.95 0.82 0.38"/>
      </geometry>
    </collision>
  </link>
  <joint name="carpet_joint" type="fixed">
    <parent link="bsen_room_link"/>
    <child link="carpet_link"/>
    <origin rpy="0 0 0" xyz="12.3 2.6 0.01"/>
  </joint>
  <link name="carpet_link">
    <visual>
      <geometry>
        <mesh filename="package://environmental_model/model/carpet.dae"/>
      </geometry>
    </visual>
    <collision>
      <geometry>
        <box size="1.76 2.55 0.01"/>
      </geometry>
    </collision>
  </link>
  <joint name="drawer_joint" type="fixed">
    <parent link="bsen_room_link"/>
    <child link="drawer_link"/>
    <origin rpy="0 0 -1.57079633" xyz="12.72 5.8 0.303"/>
  </joint>
  <link name="drawer_link">
    <visual>
      <geometry>
        <mesh filename="package://environmental_model/model/drawer.dae"/>
      </geometry>
    </visual>
    <collision>
      <geometry>
        <box size="0.6 0.4 0.6"/>
      </geometry>
    </collision>
  </link>
  <joint name="wardrobe_joint" type="fixed">
    <parent link="bsen_room_link"/>
    <child link="wardrobe_link"/>
    <origin rpy="0 0 -1.57079633" xyz="13.46 5.9 1.3"/>
  </joint>
  <link name="wardrobe_link">
    <visual>
      <geometry>
        <mesh filename="package://environmental_model/model/wardrobe.dae"/>
      </geometry>
    </visual>
    <collision>
      <geometry>
        <box size="0.7 0.95 2.56"/>
      </geometry>
    </collision>
  </link>
  <joint name="workdesk_joint" type="fixed">
    <parent link="bsen_room_link"/>
    <child link="workdesk_link"/>
    <origin rpy="0 0 -1.57079633" xyz="11.80 5.9 0.35"/>
  </joint>
  <link name="workdesk_link">
    <visual>
      <geometry>
        <mesh filename="package://environmental_model/model/work_desk.dae"/>
      </geometry>
    </visual>
    <collision>
      <geometry>
        <box size="0.65 2.44 0.7"/>
      </geometry>
    </collision>
  </link>
  <joint name="tv_multi_joint" type="fixed">
    <parent link="bsen_room_link"/>
    <child link="tv_multi_link"/>
    <origin rpy="0 0 -1.57079633" xyz="14.37 2.2 1.45"/>
  </joint>
  <link name="tv_multi_link">
    <visual>
      <geometry>
        <mesh filename="package://environmental_model/model/tv_multi.dae"/>
      </geometry>
    </visual>
    <collision>
      <geometry>
        <box size="2.5 0.2 1.4"/>
      </geometry>
    </collision>
  </link>
  <joint name="intelingent_shelf_joint" type="fixed">
    <parent link="bsen_room_link"/>
    <child link="intelingent_shelf_link"/>
    <origin rpy="0 0 0" xyz="11.65 3.970 0.005"/>
  </joint>
  <link name="intelingent_shelf_link">
    <visual>
      <geometry>
        <mesh filename="package://environmental_model/model/intelingent_shelf.dae"/>
      </geometry>
    </visual>
    <collision>
      <geometry>
        <box size="0.3 0.5 0.9"/>
      </geometry>
    </collision>
  </link>
  <joint name="refrigerator_joint" type="fixed">
    <parent link="bsen_room_link"/>
    <child link="refrigerator_link"/>
    <origin rpy="0 0 -1.57079633" xyz="6.94 5.53 -0.01"/>
  </joint>
  <link name="refrigerator_link">
    <visual>
      <geometry>
        <mesh filename="package://environmental_model/model/refrigerator.dae"/>
      </geometry>
    </visual>
    <collision>
      <geometry>
        <box size="0.5 0.47 0.05"/>
      </geometry>
      <origin rpy="0 0 0" xyz="-0.32 0.235 1.09"/>
    </collision>
  </link>
  <joint name="refrigerator_door_joint" type="continuous">
    <parent link="refrigerator_link"/>
    <child link="refrigerator_door_link"/>
    <origin rpy="0 0 0" xyz="-0.035 0.45 1.06"/>
    <axis xyz="0 0 1"/>
  </joint>
  <link name="refrigerator_door_link">
    <visual>
      <geometry>
        <mesh filename="package://environmental_model/model/refrigerator_door.dae"/>
      </geometry>
    </visual>
    <collision>
      <geometry>
        <cylinder length="0.001" radius="0.001"/>
      </geometry>
    </collision>
  </link>
  <joint name="meeting_door_joint" type="fixed">
    <parent link="bsen_room_link"/>
    <child link="meeting_door_link"/>
    <origin rpy="0 0 3.14159" xyz="1.94 3.035 1.31"/>
  </joint>
  <link name="meeting_door_link">
    <visual>
      <geometry>
        <mesh filename="package://environmental_model/model/meeting_door.dae"/>
      </geometry>
    </visual>
    <collision>
      <geometry>
        <box size="0.03 1.23 0.9"/>
      </geometry>
    </collision>
  </link>
  <!-- chair -->
  <link name="chair_x_link"/>
  <joint name="chair_x_joint" type="prismatic">
    <parent link="world_link"/>
    <child link="chair_x_link"/>
    <origin rpy="0 0 0" xyz="0 0 0"/>
    <limit effort="1000.0" lower="0." upper="15." velocity="0.5"/>
  </joint>
  <link name="chair_y_link"/>
  <joint name="chair_y_joint" type="prismatic">
    <parent link="chair_x_link"/>
    <child link="chair_y_link"/>
    <origin rpy="0 0 1.57079633" xyz="0 0 0"/>
    <limit effort="1000.0" lower="0." upper="8." velocity="0.5"/>
  </joint>
  <joint name="chair_yaw_joint" type="continuous">
    <parent link="chair_y_link"/>
    <child link="chair_link"/>
    <origin rpy="0 0 0" xyz="0 0 0"/>
    <axis xyz="0 0 1"/>
  </joint>
  <link name="chair_link">
    <visual>
      <geometry>
        <mesh filename="package://environmental_model/model/chair.dae"/>
      </geometry>
      <origin rpy="0.0 0.0 0.0" xyz="0.0 0.0 0.51"/>
    </visual>
    <collision>
      <geometry>
        <cylinder length="1.1" radius="0.35"/>
      </geometry>
      <origin rpy="0.0 0.0 0.0" xyz="0.0 0.0 0.51"/>
    </collision>
  </link>
  <!-- refrigerator -->
  <!--     <link name="refrigerator_x_link"/>

    <joint name="refrigerator_x_joint" type="prismatic">
      <parent link="world_link"/>
      <child link="refrigerator_x_link"/>
      <origin xyz="0 0 0" rpy="0 0 0"/>
      <limit effort="1000.0" lower="0." upper="15." velocity="0.5"/>
    </joint>

    <link name="refrigerator_y_link"/>

    <joint name="refrigerator_y_joint" type="prismatic">
      <parent link="refrigerator_x_link"/>
      <child link="refrigerator_y_link"/>
      <origin xyz="0 0 0" rpy="0 0 1.57079633"/>
      <limit effort="1000.0" lower="0." upper="8." velocity="0.5"/>
    </joint>

    <joint name="refrigerator_yaw_joint" type="continuous">
      <parent link="refrigerator_y_link"/>
      <child link="refrigerator_link"/>
      <origin xyz="0 0 0" rpy="0 0 0"/>
      <axis xyz="0 0 1"/>
    </joint>

    <link name="refrigerator_link">
      <visual>
        <geometry>
          <mesh filename="package://environmental_model/model/refrigerator.dae"/>
        </geometry>
        <origin xyz="0.0 0.0 0.56" rpy="0 0 0"/>
      </visual>
      <collision>
        <geometry>
          <box size="0.6 0.5 1.1"/>
        </geometry>
        <origin xyz="0.0 0.0 0.56" rpy="0 0 0"/>
      </collision>
    </link> -->
  <link name="meeting_chair1_x_link"/>
  <joint name="meeting_chair1_x_joint" type="prismatic">
    <parent link="world_link"/>
    <child link="meeting_chair1_x_link"/>
    <origin rpy="0 0 0" xyz="0 0 0"/>
    <limit effort="1000.0" lower="0." upper="15." velocity="0.5"/>
  </joint>
  <link name="meeting_chair1_y_link"/>
  <joint name="meeting_chair1_y_joint" type="prismatic">
    <parent link="meeting_chair1_x_link"/>
    <child link="meeting_chair1_y_link"/>
    <origin rpy="0 0 1.57079633" xyz="0 0 0"/>
    <limit effort="1000.0" lower="0." upper="8." velocity="0.5"/>
  </joint>
  <joint name="meeting_chair1_yaw_joint" type="continuous">
    <parent link="meeting_chair1_y_link"/>
    <child link="meeting_chair1_link"/>
    <origin rpy="0 0 0" xyz="0 0 0"/>
    <axis xyz="0 0 1"/>
  </joint>
  <link name="meeting_chair1_link">
    <visual>
      <geometry>
        <mesh filename="package://environmental_model/model/meeting_chair.dae"/>
      </geometry>
      <origin rpy="0 0 0" xyz="0.0 0.0 0.3978"/>
    </visual>
    <collision>
      <geometry>
        <cylinder length="0.8" radius="0.35"/>
      </geometry>
      <origin rpy="0 0 0" xyz="0.0 0.0 0.3978"/>
    </collision>
  </link>
  <link name="meeting_chair2_x_link"/>
  <joint name="meeting_chair2_x_joint" type="prismatic">
    <parent link="world_link"/>
    <child link="meeting_chair2_x_link"/>
    <origin rpy="0 0 0" xyz="0 0 0"/>
    <limit effort="1000.0" lower="0." upper="15." velocity="0.5"/>
  </joint>
  <link name="meeting_chair2_y_link"/>
  <joint name="meeting_chair2_y_joint" type="prismatic">
    <parent link="meeting_chair2_x_link"/>
    <child link="meeting_chair2_y_link"/>
    <origin rpy="0 0 1.57079633" xyz="0 0 0"/>
    <limit effort="1000.0" lower="0." upper="8." velocity="0.5"/>
  </joint>
  <joint name="meeting_chair2_yaw_joint" type="continuous">
    <parent link="meeting_chair2_y_link"/>
    <child link="meeting_chair2_link"/>
    <origin rpy="0 0 0" xyz="0 0 0"/>
    <axis xyz="0 0 1"/>
  </joint>
  <link name="meeting_chair2_link">
    <visual>
      <geometry>
        <mesh filename="package://environmental_model/model/meeting_chair.dae"/>
      </geometry>
      <origin rpy="0 0 0" xyz="0.0 0.0 0.3978"/>
    </visual>
    <collision>
      <geometry>
        <cylinder length="0.8" radius="0.35"/>
      </geometry>
      <origin rpy="0 0 0" xyz="0.0 0.0 0.3978"/>
    </collision>
  </link>
  <link name="meeting_chair3_x_link"/>
  <joint name="meeting_chair3_x_joint" type="prismatic">
    <parent link="world_link"/>
    <child link="meeting_chair3_x_link"/>
    <origin rpy="0 0 0" xyz="0 0 0"/>
    <limit effort="1000.0" lower="0." upper="15." velocity="0.5"/>
  </joint>
  <link name="meeting_chair3_y_link"/>
  <joint name="meeting_chair3_y_joint" type="prismatic">
    <parent link="meeting_chair3_x_link"/>
    <child link="meeting_chair3_y_link"/>
    <origin rpy="0 0 1.57079633" xyz="0 0 0"/>
    <limit effort="1000.0" lower="0." upper="8." velocity="0.5"/>
  </joint>
  <joint name="meeting_chair3_yaw_joint" type="continuous">
    <parent link="meeting_chair3_y_link"/>
    <child link="meeting_chair3_link"/>
    <origin rpy="0 0 0" xyz="0 0 0"/>
    <axis xyz="0 0 1"/>
  </joint>
  <link name="meeting_chair3_link">
    <visual>
      <geometry>
        <mesh filename="package://environmental_model/model/meeting_chair.dae"/>
      </geometry>
      <origin rpy="0 0 0" xyz="0.0 0.0 0.3978"/>
    </visual>
    <collision>
      <geometry>
        <cylinder length="0.8" radius="0.35"/>
      </geometry>
      <origin rpy="0 0 0" xyz="0.0 0.0 0.3978"/>
    </collision>
  </link>
  <link name="meeting_chair4_x_link"/>
  <joint name="meeting_chair4_x_joint" type="prismatic">
    <parent link="world_link"/>
    <child link="meeting_chair4_x_link"/>
    <origin rpy="0 0 0" xyz="0 0 0"/>
    <limit effort="1000.0" lower="0." upper="15." velocity="0.5"/>
  </joint>
  <link name="meeting_chair4_y_link"/>
  <joint name="meeting_chair4_y_joint" type="prismatic">
    <parent link="meeting_chair4_x_link"/>
    <child link="meeting_chair4_y_link"/>
    <origin rpy="0 0 1.57079633" xyz="0 0 0"/>
    <limit effort="1000.0" lower="0." upper="8." velocity="0.5"/>
  </joint>
  <joint name="meeting_chair4_yaw_joint" type="continuous">
    <parent link="meeting_chair4_y_link"/>
    <child link="meeting_chair4_link"/>
    <origin rpy="0 0 0" xyz="0 0 0"/>
    <axis xyz="0 0 1"/>
  </joint>
  <link name="meeting_chair4_link">
    <visual>
      <geometry>
        <mesh filename="package://environmental_model/model/meeting_chair.dae"/>
      </geometry>
      <origin rpy="0 0 0" xyz="0.0 0.0 0.3978"/>
    </visual>
    <collision>
      <geometry>
        <cylinder length="0.8" radius="0.35"/>
      </geometry>
      <origin rpy="0 0 0" xyz="0.0 0.0 0.3978"/>
    </collision>
  </link>
  <!-- wagon -->
  <link name="wagon_x_link"/>
  <joint name="wagon_x_joint" type="prismatic">
    <parent link="world_link"/>
    <child link="wagon_x_link"/>
    <origin rpy="0 0 0" xyz="0 0 0"/>
    <limit effort="1000.0" lower="0." upper="15." velocity="0.5"/>
  </joint>
  <link name="wagon_y_link"/>
  <joint name="wagon_y_joint" type="prismatic">
    <parent link="wagon_x_link"/>
    <child link="wagon_y_link"/>
    <origin rpy="0 0 1.57079633" xyz="0 0 0"/>
    <limit effort="1000.0" lower="0." upper="8." velocity="0.5"/>
  </joint>
  <joint name="wagon_yaw_joint" type="continuous">
    <parent link="wagon_y_link"/>
    <child link="wagon_link"/>
    <origin rpy="0 0 0" xyz="0 0 0"/>
    <axis xyz="0 0 1"/>
  </joint>
  <link name="wagon_link">
    <visual>
      <geometry>
        <mesh filename="package://environmental_model/model/wagon.dae"/>
      </geometry>
      <origin rpy="0 0 0" xyz="0. 0. 0.3"/>
    </visual>
    <collision>
      <geometry>
        <box size="0.6 0.4 0.7"/>
      </geometry>
      <origin rpy="0 0 0" xyz="0. 0. 0.3"/>
    </collision>
  </link>
  <!-- object -->
  <!-- chipstar_red -->
  <link name="chipstar_red_x_link"/>
  <joint name="chipstar_red_x_joint" type="prismatic">
    <parent link="world_link"/>
    <child link="chipstar_red_x_link"/>
    <origin rpy="0 0 0" xyz="0 0 0"/>
    <limit effort="1000.0" lower="0." upper="15." velocity="0.5"/>
  </joint>
  <link name="chipstar_red_y_link"/>
  <joint name="chipstar_red_y_joint" type="prismatic">
    <parent link="chipstar_red_x_link"/>
    <child link="chipstar_red_y_link"/>
    <origin rpy="0 0 1.57079633" xyz="0 0 0"/>
    <limit effort="1000.0" lower="0." upper="8." velocity="0.5"/>
  </joint>
  <link name="chipstar_red_z_link"/>
  <joint name="chipstar_red_z_joint" type="prismatic">
    <parent link="chipstar_red_y_link"/>
    <child link="chipstar_red_z_link"/>
    <origin rpy="0 -1.57079633 0" xyz="0 0 0"/>
    <limit effort="1000.0" lower="0." upper="3." velocity="0.5"/>
  </joint>
  <link name="chipstar_red_yaw_link"/>
  <joint name="chipstar_red_yaw_joint" type="continuous">
    <parent link="chipstar_red_z_link"/>
    <child link="chipstar_red_yaw_link"/>
    <origin rpy="-1.57079633 0 -1.57079633" xyz="0 0 0"/>
    <axis xyz="0 0 1"/>
  </joint>
  <link name="chipstar_red_pitch_link"/>
  <joint name="chipstar_red_pitch_joint" type="continuous">
    <parent link="chipstar_red_yaw_link"/>
    <child link="chipstar_red_pitch_link"/>
    <origin rpy="0 0 0" xyz="0 0 0"/>
    <axis xyz="0 1 0"/>
  </joint>
  <joint name="chipstar_red_roll_joint" type="continuous">
    <parent link="chipstar_red_pitch_link"/>
    <child link="chipstar_red_link"/>
    <origin rpy="0 0 0" xyz="0 0 0"/>
    <axis xyz="1 0 0"/>
  </joint>
  <link name="chipstar_red_link">
    <visual>
      <geometry>
        <mesh filename="package://environmental_model/model/chipstar_red.dae"/>
      </geometry>
      <origin rpy="0 0 0" xyz="0. 0. 0."/>
    </visual>
    <collision>
      <geometry>
        <cylinder length="0.001" radius="0.001"/>
      </geometry>
      <origin rpy="0. 0. 0." xyz="0 0 0"/>
    </collision>
  </link>
  <!-- greentea_bottle -->
  <link name="greentea_bottle_x_link"/>
  <joint name="greentea_bottle_x_joint" type="prismatic">
    <parent link="world_link"/>
    <child link="greentea_bottle_x_link"/>
    <origin rpy="0 0 0" xyz="0 0 0"/>
    <limit effort="1000.0" lower="0." upper="15." velocity="0.5"/>
  </joint>
  <link name="greentea_bottle_y_link"/>
  <joint name="greentea_bottle_y_joint" type="prismatic">
    <parent link="greentea_bottle_x_link"/>
    <child link="greentea_bottle_y_link"/>
    <origin rpy="0 0 1.57079633" xyz="0 0 0"/>
    <limit effort="1000.0" lower="0." upper="8." velocity="0.5"/>
  </joint>
  <link name="greentea_bottle_z_link"/>
  <joint name="greentea_bottle_z_joint" type="prismatic">
    <parent link="greentea_bottle_y_link"/>
    <child link="greentea_bottle_z_link"/>
    <origin rpy="0 -1.57079633 0" xyz="0 0 0"/>
    <limit effort="1000.0" lower="0." upper="3." velocity="0.5"/>
  </joint>
  <link name="greentea_bottle_yaw_link"/>
  <joint name="greentea_bottle_yaw_joint" type="continuous">
    <parent link="greentea_bottle_z_link"/>
    <child link="greentea_bottle_yaw_link"/>
    <origin rpy="-1.57079633 0 -1.57079633" xyz="0 0 0"/>
    <axis xyz="0 0 1"/>
  </joint>
  <link name="greentea_bottle_pitch_link"/>
  <joint name="greentea_bottle_pitch_joint" type="continuous">
    <parent link="greentea_bottle_yaw_link"/>
    <child link="greentea_bottle_pitch_link"/>
    <origin rpy="0 0 0" xyz="0 0 0"/>
    <axis xyz="0 1 0"/>
  </joint>
  <joint name="greentea_bottle_roll_joint" type="continuous">
    <parent link="greentea_bottle_pitch_link"/>
    <child link="greentea_bottle_link"/>
    <origin rpy="0 0 0" xyz="0 0 0"/>
    <axis xyz="1 0 0"/>
  </joint>
  <link name="greentea_bottle_link">
    <visual>
      <geometry>
        <mesh filename="package://environmental_model/model/greentea_bottle.dae"/>
      </geometry>
      <origin rpy="0 0 0" xyz="0. 0. 0."/>
    </visual>
    <collision>
      <geometry>
        <cylinder length="0.001" radius="0.001"/>
      </geometry>
      <origin rpy="0. 0. 0." xyz="0 0 0"/>
    </collision>
  </link>
  <!-- cancoffee -->
  <link name="cancoffee_x_link"/>
  <joint name="cancoffee_x_joint" type="prismatic">
    <parent link="world_link"/>
    <child link="cancoffee_x_link"/>
    <origin rpy="0 0 0" xyz="0 0 0"/>
    <limit effort="1000.0" lower="0." upper="15." velocity="0.5"/>
  </joint>
  <link name="cancoffee_y_link"/>
  <joint name="cancoffee_y_joint" type="prismatic">
    <parent link="cancoffee_x_link"/>
    <child link="cancoffee_y_link"/>
    <origin rpy="0 0 1.57079633" xyz="0 0 0"/>
    <limit effort="1000.0" lower="0." upper="8." velocity="0.5"/>
  </joint>
  <link name="cancoffee_z_link"/>
  <joint name="cancoffee_z_joint" type="prismatic">
    <parent link="cancoffee_y_link"/>
    <child link="cancoffee_z_link"/>
    <origin rpy="0 -1.57079633 0" xyz="0 0 0"/>
    <limit effort="1000.0" lower="0." upper="3." velocity="0.5"/>
  </joint>
  <link name="cancoffee_yaw_link"/>
  <joint name="cancoffee_yaw_joint" type="continuous">
    <parent link="cancoffee_z_link"/>
    <child link="cancoffee_yaw_link"/>
    <origin rpy="-1.57079633 0 -1.57079633" xyz="0 0 0"/>
    <axis xyz="0 0 1"/>
  </joint>
  <link name="cancoffee_pitch_link"/>
  <joint name="cancoffee_pitch_joint" type="continuous">
    <parent link="cancoffee_yaw_link"/>
    <child link="cancoffee_pitch_link"/>
    <origin rpy="0 0 0" xyz="0 0 0"/>
    <axis xyz="0 1 0"/>
  </joint>
  <joint name="cancoffee_roll_joint" type="continuous">
    <parent link="cancoffee_pitch_link"/>
    <child link="cancoffee_link"/>
    <origin rpy="0 0 0" xyz="0 0 0"/>
    <axis xyz="1 0 0"/>
  </joint>
  <link name="cancoffee_link">
    <visual>
      <geometry>
        <mesh filename="package://environmental_model/model/cancoffee.dae"/>
      </geometry>
      <origin rpy="0 0 0" xyz="0. 0. 0."/>
    </visual>
    <collision>
      <geometry>
        <cylinder length="0.001" radius="0.001"/>
      </geometry>
      <origin rpy="0. 0. 0." xyz="0 0 0"/>
    </collision>
  </link>
  <!-- soysauce_bottle_black -->
  <link name="soysauce_bottle_black_x_link"/>
  <joint name="soysauce_bottle_black_x_joint" type="prismatic">
    <parent link="world_link"/>
    <child link="soysauce_bottle_black_x_link"/>
    <origin rpy="0 0 0" xyz="0 0 0"/>
    <limit effort="1000.0" lower="0." upper="15." velocity="0.5"/>
  </joint>
  <link name="soysauce_bottle_black_y_link"/>
  <joint name="soysauce_bottle_black_y_joint" type="prismatic">
    <parent link="soysauce_bottle_black_x_link"/>
    <child link="soysauce_bottle_black_y_link"/>
    <origin rpy="0 0 1.57079633" xyz="0 0 0"/>
    <limit effort="1000.0" lower="0." upper="8." velocity="0.5"/>
  </joint>
  <link name="soysauce_bottle_black_z_link"/>
  <joint name="soysauce_bottle_black_z_joint" type="prismatic">
    <parent link="soysauce_bottle_black_y_link"/>
    <child link="soysauce_bottle_black_z_link"/>
    <origin rpy="0 -1.57079633 0" xyz="0 0 0"/>
    <limit effort="1000.0" lower="0." upper="3." velocity="0.5"/>
  </joint>
  <link name="soysauce_bottle_black_yaw_link"/>
  <joint name="soysauce_bottle_black_yaw_joint" type="continuous">
    <parent link="soysauce_bottle_black_z_link"/>
    <child link="soysauce_bottle_black_yaw_link"/>
    <origin rpy="-1.57079633 0 -1.57079633" xyz="0 0 0"/>
    <axis xyz="0 0 1"/>
  </joint>
  <link name="soysauce_bottle_black_pitch_link"/>
  <joint name="soysauce_bottle_black_pitch_joint" type="continuous">
    <parent link="soysauce_bottle_black_yaw_link"/>
    <child link="soysauce_bottle_black_pitch_link"/>
    <origin rpy="0 0 0" xyz="0 0 0"/>
    <axis xyz="0 1 0"/>
  </joint>
  <joint name="soysauce_bottle_black_roll_joint" type="continuous">
    <parent link="soysauce_bottle_black_pitch_link"/>
    <child link="soysauce_bottle_black_link"/>
    <origin rpy="0 0 0" xyz="0 0 0"/>
    <axis xyz="1 0 0"/>
  </joint>
  <link name="soysauce_bottle_black_link">
    <visual>
      <geometry>
        <mesh filename="package://environmental_model/model/soysauce_bottle_black.dae"/>
      </geometry>
      <origin rpy="0 0 0" xyz="0. 0. 0."/>
    </visual>
    <collision>
      <geometry>
        <cylinder length="0.001" radius="0.001"/>
      </geometry>
      <origin rpy="0. 0. 0." xyz="0 0 0"/>
    </collision>
  </link>
  <!-- ros_control plugin -->
  <gazebo>
    <plugin filename="libgazebo_ros_control.so" name="gazebo_ros_control">
      <robotNamespace>/smartpal</robotNamespace>
      <robotSimType>gazebo_ros_control/DefaultRobotHWSim</robotSimType>
    </plugin>
  </gazebo>
  <gazebo reference="base_link">
  </gazebo>
  <gazebo reference="lumbar_lower_link">
  </gazebo>
  <gazebo reference="lumbar_upper_link">
  </gazebo>
  <gazebo reference="camera_link">
  </gazebo>
  <gazebo reference="l_arm_j1_link">
  </gazebo>
  <gazebo reference="l_arm_j2_link">
  </gazebo>
  <gazebo reference="l_arm_j3_link">
  </gazebo>
  <gazebo reference="l_arm_j4_link">
  </gazebo>
  <gazebo reference="l_arm_j5_link">
  </gazebo>
  <gazebo reference="l_arm_j6_link">
  </gazebo>
  <gazebo reference="l_arm_j7_link">
  </gazebo>
  <gazebo reference="l_gripper_link">
  </gazebo>
  <gazebo reference="l_end_effector_link">
  </gazebo>
  <gazebo reference="l_gripper_thumb_link">
  </gazebo>
  <gazebo reference="r_arm_j1_link">
  </gazebo>
  <gazebo reference="r_arm_j2_link">
  </gazebo>
  <gazebo reference="r_arm_j3_link">
  </gazebo>
  <gazebo reference="r_arm_j4_link">
  </gazebo>
  <gazebo reference="r_arm_j5_link">
  </gazebo>
  <gazebo reference="r_arm_j6_link">
  </gazebo>
  <gazebo reference="r_arm_j7_link">
  </gazebo>
  <gazebo reference="r_gripper_link">
  </gazebo>
  <gazebo reference="r_end_effector_link">
  </gazebo>
  <gazebo reference="r_gripper_thumb_link">
  </gazebo>
  <!-- Base, Vehicle -->
  <link name="smartpal5_link"/>
  <joint name="smartpal5_x_joint" type="prismatic">
    <parent link="smartpal5_link"/>
    <child link="smartpal5_x_link"/>
    <origin rpy="0 0 0" xyz="0 0 0"/>
    <limit effort="1000.0" lower="-5." upper="5." velocity="0.5"/>
  </joint>
  <link name="smartpal5_x_link"/>
  <joint name="smartpal5_y_joint" type="prismatic">
    <parent link="smartpal5_x_link"/>
    <child link="smartpal5_y_link"/>
    <origin rpy="0 0 1.57075" xyz="0 0 0"/>
    <limit effort="1000.0" lower="-5." upper="5." velocity="0.5"/>
  </joint>
  <link name="smartpal5_y_link"/>
  <joint name="smartpal5_yaw_joint" type="continuous">
    <parent link="smartpal5_y_link"/>
    <child link="base_footprint"/>
    <origin rpy="0 0 -1.57075" xyz="0 0 0"/>
    <axis xyz="0 0 1"/>
  </joint>
  <link name="base_footprint"/>
  <joint name="base_footprint_joint" type="fixed">
    <parent link="base_footprint"/>
    <child link="base_link"/>
    <origin rpy="0 0 0" xyz="0 0 0"/>
  </joint>
  <link name="base_link">
    <visual>
      <geometry>
        <mesh filename="package://smartpal5_description/meshes/visual/Pal5_body_vehicle.dae"/>
      </geometry>
      <origin rpy="0 0 0" xyz="0 0 0"/>
      <!-- Offset for wheels already included in the mesh definition -->
      <material name="grey"/>
    </visual>
    <collision>
      <geometry>
        <mesh filename="package://smartpal5_description/meshes/collision/Pal5_body_vehicle.dae"/>
      </geometry>
      <origin rpy="0 0 0" xyz="0 0 0"/>
    </collision>
    <inertial>
      <origin rpy="0 0 0" xyz="0 0 0.0375"/>
      <mass value="27"/>
      <inertia ixx="1.0" ixy="0.0" ixz="0.0" iyy="1.0" iyz="0.0" izz="1.0"/>
    </inertial>
  </link>
  <!-- Lumbar -->
  <joint name="lumbar_lower_joint" type="revolute">
    <parent link="base_link"/>
    <child link="lumbar_lower_link"/>
    <origin rpy="-1.57075 0 0" xyz="0 0 0.4365"/>
    <axis xyz="0 0 1"/>
    <limit effort="100.0" lower="-0.2" upper="0.00872664625997165" velocity="1.0"/>
  </joint>
  <link name="lumbar_lower_link">
    <visual>
      <geometry>
        <mesh filename="package://smartpal5_description/meshes/visual/Pal5_body_lumbar-J1.dae"/>
      </geometry>
      <origin rpy="0 0 0" xyz="0 0 0"/>
      <material name="grey"/>
    </visual>
    <collision>
      <geometry>
        <mesh filename="package://smartpal5_description/meshes/collision/Pal5_body_lumbar-J1.dae"/>
      </geometry>
      <origin rpy="0 0 0" xyz="0 0 0"/>
    </collision>
    <inertial>
      <origin rpy="0 0 0" xyz="0 0 -0.1"/>
      <mass value="6"/>
      <inertia ixx="1.0" ixy="0.0" ixz="0.0" iyy="1.0" iyz="0.0" izz="1.0"/>
    </inertial>
  </link>
  <joint name="lumbar_upper_joint" type="revolute">
    <parent link="lumbar_lower_link"/>
    <child link="lumbar_upper_link"/>
    <origin rpy="0 0 0" xyz="0 -0.21 0"/>
    <axis xyz="0 0 1"/>
    <limit effort="100.0" lower="-0.00872664625997165" upper="2.10312174865317" velocity="1.0"/>
  </joint>
  <link name="lumbar_upper_link">
    <visual>
      <geometry>
        <mesh filename="package://smartpal5_description/meshes/visual/Pal5_body_lumbar-J2.dae"/>
      </geometry>
      <origin rpy="0 0 0" xyz="0 0 0"/>
      <material name="grey"/>
    </visual>
    <collision>
      <geometry>
        <mesh filename="package://smartpal5_description/meshes/collision/Pal5_body_lumbar-J2.dae"/>
      </geometry>
      <origin rpy="0 0 0" xyz="0 0 0"/>
    </collision>
    <inertial>
      <origin rpy="0 0 0" xyz="0.11 0 0.25"/>
      <mass value="30"/>
      <inertia ixx="1.0" ixy="0.0" ixz="0.0" iyy="1.0" iyz="0.0" izz="1.0"/>
    </inertial>
  </link>
  <!-- RGB-D Camera -->
  <joint name="head_camera_joint" type="fixed">
    <parent link="lumbar_upper_link"/>
    <child link="camera_link"/>
    <origin rpy="1.57075 0 0" xyz="0.02 -0.7 0"/>
  </joint>
  <link name="camera_link">
    <visual>
      <geometry>
        <box size="0.03 0.15 0.05"/>
      </geometry>
      <origin rpy="0 0 0" xyz="0 0 0"/>
      <material name="grey"/>
    </visual>
    <collision>
      <geometry>
        <box size="0.05 0.2 0.08"/>
      </geometry>
      <origin rpy="0 0 0" xyz="0 0 0"/>
    </collision>
    <inertial>
      <origin rpy="0 0 0" xyz="0 0 0"/>
      <mass value="0.5"/>
      <inertia ixx="1.0" ixy="0.0" ixz="0.0" iyy="1.0" iyz="0.0" izz="1.0"/>
    </inertial>
  </link>
  <!-- Left Arm -->
  <joint name="l_arm_j1_joint" type="revolute">
    <parent link="lumbar_upper_link"/>
    <child link="l_arm_j1_link"/>
    <origin rpy="3.14159 0 0" xyz="-0.025 -0.480 0.200"/>
    <axis xyz="0 0 1"/>
    <limit effort="100.0" lower="-0.76" upper="3.12" velocity="1.0"/>
  </joint>
  <link name="l_arm_j1_link">
    <visual>
      <geometry>
        <mesh filename="package://smartpal5_description/meshes/visual/Pal5_leftArm_J1.dae"/>
      </geometry>
      <origin rpy="0 0 0" xyz="0 0 0"/>
      <material name="grey"/>
    </visual>
    <collision>
      <geometry>
        <mesh filename="package://smartpal5_description/meshes/collision/Pal5_leftArm_J1.dae"/>
      </geometry>
      <origin rpy="0 0 0" xyz="0 0 0"/>
    </collision>
    <inertial>
      <origin rpy="0 0 0" xyz="0 0 -0.1"/>
      <mass value="0.6"/>
      <inertia ixx="1.0" ixy="0.0" ixz="0.0" iyy="1.0" iyz="0.0" izz="1.0"/>
    </inertial>
  </link>
  <joint name="l_arm_j2_joint" type="revolute">
    <parent link="l_arm_j1_link"/>
    <child link="l_arm_j2_link"/>
    <origin rpy="1.57075 3.14159 1.57075" xyz="0 0 0"/>
    <axis xyz="0 0 -1"/>
    <limit effort="100.0" lower="-1.8" upper="0.21" velocity="1.0"/>
  </joint>
  <link name="l_arm_j2_link">
    <visual>
      <geometry>
        <mesh filename="package://smartpal5_description/meshes/visual/Pal5_leftArm_J2.dae"/>
      </geometry>
      <origin rpy="0 0 0" xyz="0 0 0"/>
      <material name="grey"/>
    </visual>
    <collision>
      <geometry>
        <mesh filename="package://smartpal5_description/meshes/collision/Pal5_leftArm_J2.dae"/>
      </geometry>
      <origin rpy="0 0 0" xyz="0 0 0"/>
    </collision>
    <inertial>
      <origin rpy="0 0 0" xyz="0 0 -0.1"/>
      <mass value="0.6"/>
      <inertia ixx="1.0" ixy="0.0" ixz="0.0" iyy="1.0" iyz="0.0" izz="1.0"/>
    </inertial>
  </link>
  <joint name="l_arm_j3_joint" type="revolute">
    <parent link="l_arm_j2_link"/>
    <child link="l_arm_j3_link"/>
    <origin rpy="1.57075 1.57075 1.57075" xyz="0 0 0"/>
    <axis xyz="0 0 -1"/>
    <limit effort="100.0" lower="-2.0" upper="2.0" velocity="1.0"/>
  </joint>
  <link name="l_arm_j3_link">
    <visual>
      <geometry>
        <mesh filename="package://smartpal5_description/meshes/visual/Pal5_leftArm_J3.dae"/>
      </geometry>
      <origin rpy="0 0 0" xyz="0 0 0"/>
      <material name="grey"/>
    </visual>
    <collision>
      <geometry>
        <mesh filename="package://smartpal5_description/meshes/collision/Pal5_leftArm_J3.dae"/>
      </geometry>
      <origin rpy="0 0 0" xyz="0 0 0"/>
    </collision>
    <inertial>
      <origin rpy="0 0 0" xyz="0 0 0"/>
      <mass value="1"/>
      <inertia ixx="1.0" ixy="0.0" ixz="0.0" iyy="1.0" iyz="0.0" izz="1.0"/>
    </inertial>
  </link>
  <joint name="l_arm_j4_joint" type="revolute">
    <parent link="l_arm_j3_link"/>
    <child link="l_arm_j4_link"/>
    <origin rpy="-1.57075 0 3.14159" xyz="-0.02 0.0 0.25"/>
    <axis xyz="0 0 1"/>
    <limit effort="100.0" lower="-0.0" upper="2.2" velocity="1.0"/>
  </joint>
  <link name="l_arm_j4_link">
    <visual>
      <geometry>
        <mesh filename="package://smartpal5_description/meshes/visual/Pal5_leftArm_J4.dae"/>
      </geometry>
      <origin rpy="0 0 0" xyz="0 0 0"/>
      <material name="grey"/>
    </visual>
    <collision>
      <geometry>
        <mesh filename="package://smartpal5_description/meshes/collision/Pal5_leftArm_J4.dae"/>
      </geometry>
      <origin rpy="0 0 0" xyz="0 0 0"/>
    </collision>
    <inertial>
      <origin rpy="0 0 0" xyz="0 0 -0.3"/>
      <mass value="0.6"/>
      <inertia ixx="1.0" ixy="0.0" ixz="0.0" iyy="1.0" iyz="0.0" izz="1.0"/>
    </inertial>
  </link>
  <joint name="l_arm_j5_joint" type="revolute">
    <parent link="l_arm_j4_link"/>
    <child link="l_arm_j5_link"/>
    <origin rpy="1.57075 0 0" xyz="-0.02 0.0 0.0"/>
    <axis xyz="0 0 -1"/>
    <limit effort="100.0" lower="-2.0" upper="2.0" velocity="1.0"/>
  </joint>
  <link name="l_arm_j5_link">
    <visual>
      <geometry>
        <mesh filename="package://smartpal5_description/meshes/visual/Pal5_leftArm_J5.dae"/>
      </geometry>
      <origin rpy="0 0 0" xyz="0 0 0"/>
      <material name="grey"/>
    </visual>
    <collision>
      <geometry>
        <mesh filename="package://smartpal5_description/meshes/collision/Pal5_leftArm_J5.dae"/>
      </geometry>
      <origin rpy="0 0 0" xyz="0 0 0"/>
    </collision>
    <inertial>
      <origin rpy="0 0 0" xyz="0 0 0.1"/>
      <mass value="0.4"/>
      <inertia ixx="1.0" ixy="0.0" ixz="0.0" iyy="1.0" iyz="0.0" izz="1.0"/>
    </inertial>
  </link>
  <joint name="l_arm_j6_joint" type="revolute">
    <parent link="l_arm_j5_link"/>
    <child link="l_arm_j6_link"/>
    <origin rpy="-1.57075 1.57075 0" xyz="0.0 0.0 0.28"/>
    <axis xyz="0 0 1"/>
    <limit effort="100.0" lower="-0.25" upper="0.75" velocity="1.0"/>
  </joint>
  <link name="l_arm_j6_link">
    <visual>
      <geometry>
        <mesh filename="package://smartpal5_description/meshes/visual/Pal5_leftArm_J6.dae"/>
      </geometry>
      <origin rpy="0 0 0" xyz="0 0 0"/>
      <material name="grey"/>
    </visual>
    <collision>
      <geometry>
        <mesh filename="package://smartpal5_description/meshes/collision/Pal5_leftArm_J6.dae"/>
      </geometry>
      <origin rpy="0 0 0" xyz="0 0 0"/>
    </collision>
    <inertial>
      <origin rpy="0 0 0" xyz="-0.1 0 0"/>
      <mass value="0.4"/>
      <inertia ixx="1.0" ixy="0.0" ixz="0.0" iyy="1.0" iyz="0.0" izz="1.0"/>
    </inertial>
  </link>
  <joint name="l_arm_j7_joint" type="revolute">
    <parent link="l_arm_j6_link"/>
    <child link="l_arm_j7_link"/>
    <origin rpy="1.57075 3.14159 0" xyz="0.0 0.0 0"/>
    <axis xyz="0 0 1"/>
    <limit effort="100.0" lower="-1.5" upper="0.8" velocity="1.0"/>
  </joint>
  <link name="l_arm_j7_link">
    <visual>
      <geometry>
        <mesh filename="package://smartpal5_description/meshes/visual/Pal5_leftArm_J7.dae"/>
      </geometry>
      <origin rpy="0 0 0" xyz="0 0 0"/>
      <material name="grey"/>
    </visual>
    <collision>
      <geometry>
        <mesh filename="package://smartpal5_description/meshes/collision/Pal5_leftArm_J7.dae"/>
      </geometry>
      <origin rpy="0 0 0" xyz="0 0 0"/>
    </collision>
    <inertial>
      <origin rpy="0 0 0" xyz="0 0 -0.1"/>
      <mass value="0.4"/>
      <inertia ixx="1.0" ixy="0.0" ixz="0.0" iyy="1.0" iyz="0.0" izz="1.0"/>
    </inertial>
  </link>
  <!-- Left Gripper -->
  <joint name="l_gripper_joint" type="fixed">
    <parent link="l_arm_j7_link"/>
    <child link="l_gripper_link"/>
    <origin rpy="3.14159 3.14159 1.57075" xyz="0.056 0 0"/>
    <axis xyz="0 0 1"/>
  </joint>
  <link name="l_gripper_link">
    <visual>
      <geometry>
        <mesh filename="package://smartpal5_description/meshes/visual/Pal5_leftGripper_gripper.dae"/>
      </geometry>
      <origin rpy="0 0 0" xyz="0 0 0"/>
      <material name="grey"/>
    </visual>
    <collision>
      <geometry>
        <mesh filename="package://smartpal5_description/meshes/collision/Pal5_leftGripper_gripper.dae"/>
      </geometry>
      <origin rpy="0 0 0" xyz="0 0 0"/>
    </collision>
    <inertial>
      <origin rpy="0 0 0" xyz="0 0 -0.1"/>
      <mass value="0.6"/>
      <inertia ixx="1.0" ixy="0.0" ixz="0.0" iyy="1.0" iyz="0.0" izz="1.0"/>
    </inertial>
  </link>
  <joint name="l_end_effector_joint" type="fixed">
    <origin rpy="0 0 0" xyz="0.01 0.11 0"/>
    <parent link="l_gripper_link"/>
    <child link="l_end_effector_link"/>
  </joint>
  <link name="l_end_effector_link">
    <visual>
      <origin rpy="0 0 0" xyz="0 0 0"/>
      <geometry>
        <box size="0.001 0.001 0.001"/>
      </geometry>
    </visual>
    <collision>
      <origin rpy="0 0 0" xyz="0 0 0"/>
      <geometry>
        <box size="0.001 0.001 0.001"/>
      </geometry>
    </collision>
  </link>
  <joint name="l_gripper_thumb_joint" type="revolute">
    <parent link="l_gripper_link"/>
    <child link="l_gripper_thumb_link"/>
    <origin rpy="0 0 0" xyz="0.027 0.042 0.0"/>
    <axis xyz="0 0 1"/>
    <limit effort="100.0" lower="-1.0122" upper="0.1396" velocity="1.0"/>
  </joint>
  <link name="l_gripper_thumb_link">
    <visual>
      <geometry>
        <mesh filename="package://smartpal5_description/meshes/visual/Pal5_leftGripper_g-thumb.dae"/>
      </geometry>
      <origin rpy="0 0 0" xyz="0 0 0"/>
      <material name="grey"/>
    </visual>
    <collision>
      <geometry>
        <mesh filename="package://smartpal5_description/meshes/collision/Pal5_leftGripper_g-thumb.dae"/>
      </geometry>
      <origin rpy="0 0 0" xyz="0 0 0"/>
    </collision>
    <inertial>
      <origin rpy="0 0 0" xyz="0 0 -0.1"/>
      <mass value="0.4"/>
      <inertia ixx="1.0" ixy="0.0" ixz="0.0" iyy="1.0" iyz="0.0" izz="1.0"/>
    </inertial>
  </link>
  <!-- Right Arm -->
  <joint name="r_arm_j1_joint" type="revolute">
    <parent link="lumbar_upper_link"/>
    <child link="r_arm_j1_link"/>
    <origin rpy="3.14159 0 0" xyz="-0.025 -0.480 -0.200"/>
    <axis xyz="0 0 1"/>
    <limit effort="100.0" lower="-0.76" upper="3.12" velocity="1.0"/>
  </joint>
  <link name="r_arm_j1_link">
    <visual>
      <geometry>
        <mesh filename="package://smartpal5_description/meshes/visual/Pal5_rightArm_J1.dae"/>
      </geometry>
      <origin rpy="0 0 0" xyz="0 0 0"/>
      <material name="grey"/>
    </visual>
    <collision>
      <geometry>
        <mesh filename="package://smartpal5_description/meshes/collision/Pal5_rightArm_J1.dae"/>
      </geometry>
      <origin rpy="0 0 0" xyz="0 0 0"/>
    </collision>
    <inertial>
      <origin rpy="0 0 0" xyz="0 0 -0.1"/>
      <mass value="0.6"/>
      <inertia ixx="1.0" ixy="0.0" ixz="0.0" iyy="1.0" iyz="0.0" izz="1.0"/>
    </inertial>
  </link>
  <joint name="r_arm_j2_joint" type="revolute">
    <parent link="r_arm_j1_link"/>
    <child link="r_arm_j2_link"/>
    <origin rpy="-1.57075 0 -1.57075" xyz="0 0 0"/>
    <axis xyz="0 0 1"/>
    <limit effort="100.0" lower="-1.8" upper="0.21" velocity="1.0"/>
  </joint>
  <link name="r_arm_j2_link">
    <visual>
      <geometry>
        <mesh filename="package://smartpal5_description/meshes/visual/Pal5_rightArm_J2.dae"/>
      </geometry>
      <origin rpy="0 0 0" xyz="0 0 0"/>
      <material name="grey"/>
    </visual>
    <collision>
      <geometry>
        <mesh filename="package://smartpal5_description/meshes/collision/Pal5_rightArm_J2.dae"/>
      </geometry>
      <origin rpy="0 0 0" xyz="0 0 0"/>
    </collision>
    <inertial>
      <origin rpy="0 0 0" xyz="0 0 -0.1"/>
      <mass value="0.6"/>
      <inertia ixx="1.0" ixy="0.0" ixz="0.0" iyy="1.0" iyz="0.0" izz="1.0"/>
    </inertial>
  </link>
  <joint name="r_arm_j3_joint" type="revolute">
    <parent link="r_arm_j2_link"/>
    <child link="r_arm_j3_link"/>
    <origin rpy="1.57075 1.57075 1.57075" xyz="0 0 0"/>
    <axis xyz="0 0 1"/>
    <limit effort="100.0" lower="-2.0" upper="2.0" velocity="1.0"/>
  </joint>
  <link name="r_arm_j3_link">
    <visual>
      <geometry>
        <mesh filename="package://smartpal5_description/meshes/visual/Pal5_rightArm_J3.dae"/>
      </geometry>
      <origin rpy="0 0 0" xyz="0 0 0"/>
      <material name="grey"/>
    </visual>
    <collision>
      <geometry>
        <mesh filename="package://smartpal5_description/meshes/collision/Pal5_rightArm_J3.dae"/>
      </geometry>
      <origin rpy="0 0 0" xyz="0 0 0"/>
    </collision>
    <inertial>
      <origin rpy="0 0 0" xyz="0 0 0"/>
      <mass value="1"/>
      <inertia ixx="1.0" ixy="0.0" ixz="0.0" iyy="1.0" iyz="0.0" izz="1.0"/>
    </inertial>
  </link>
  <joint name="r_arm_j4_joint" type="revolute">
    <parent link="r_arm_j3_link"/>
    <child link="r_arm_j4_link"/>
    <origin rpy="-1.57075 0 3.14159" xyz="-0.02 0.0 0.25"/>
    <axis xyz="0 0 1"/>
    <limit effort="100.0" lower="-0.0" upper="2.2" velocity="1.0"/>
  </joint>
  <link name="r_arm_j4_link">
    <visual>
      <geometry>
        <mesh filename="package://smartpal5_description/meshes/visual/Pal5_rightArm_J4.dae"/>
      </geometry>
      <origin rpy="0 0 0" xyz="0 0 0"/>
      <material name="grey"/>
    </visual>
    <collision>
      <geometry>
        <mesh filename="package://smartpal5_description/meshes/collision/Pal5_rightArm_J4.dae"/>
      </geometry>
      <origin rpy="0 0 0" xyz="0 0 0"/>
    </collision>
    <inertial>
      <origin rpy="0 0 0" xyz="0 0 -0.3"/>
      <mass value="0.6"/>
      <inertia ixx="1.0" ixy="0.0" ixz="0.0" iyy="1.0" iyz="0.0" izz="1.0"/>
    </inertial>
  </link>
  <joint name="r_arm_j5_joint" type="revolute">
    <parent link="r_arm_j4_link"/>
    <child link="r_arm_j5_link"/>
    <origin rpy="1.57075 0 0" xyz="-0.02 0.0 0.0"/>
    <axis xyz="0 0 1"/>
    <limit effort="100.0" lower="-2.0" upper="2.0" velocity="1.0"/>
  </joint>
  <link name="r_arm_j5_link">
    <visual>
      <geometry>
        <mesh filename="package://smartpal5_description/meshes/visual/Pal5_rightArm_J5.dae"/>
      </geometry>
      <origin rpy="0 0 0" xyz="0 0 0"/>
      <material name="grey"/>
    </visual>
    <collision>
      <geometry>
        <mesh filename="package://smartpal5_description/meshes/collision/Pal5_rightArm_J5.dae"/>
      </geometry>
      <origin rpy="0 0 0" xyz="0 0 0"/>
    </collision>
    <inertial>
      <origin rpy="0 0 0" xyz="0 0 0.1"/>
      <mass value="0.4"/>
      <inertia ixx="1.0" ixy="0.0" ixz="0.0" iyy="1.0" iyz="0.0" izz="1.0"/>
    </inertial>
  </link>
  <joint name="r_arm_j6_joint" type="revolute">
    <parent link="r_arm_j5_link"/>
    <child link="r_arm_j6_link"/>
    <origin rpy="-1.57075 1.57075 0" xyz="0.0 0.0 0.28"/>
    <axis xyz="0 0 1"/>
    <limit effort="100.0" lower="-0.25" upper="0.75" velocity="1.0"/>
  </joint>
  <link name="r_arm_j6_link">
    <visual>
      <geometry>
        <mesh filename="package://smartpal5_description/meshes/visual/Pal5_rightArm_J6.dae"/>
      </geometry>
      <origin rpy="0 0 0" xyz="0 0 0"/>
      <material name="grey"/>
    </visual>
    <collision>
      <geometry>
        <mesh filename="package://smartpal5_description/meshes/collision/Pal5_rightArm_J6.dae"/>
      </geometry>
      <origin rpy="0 0 0" xyz="0 0 0"/>
    </collision>
    <inertial>
      <origin rpy="0 0 0" xyz="-0.1 0 0"/>
      <mass value="0.4"/>
      <inertia ixx="1.0" ixy="0.0" ixz="0.0" iyy="1.0" iyz="0.0" izz="1.0"/>
    </inertial>
  </link>
  <joint name="r_arm_j7_joint" type="revolute">
    <parent link="r_arm_j6_link"/>
    <child link="r_arm_j7_link"/>
    <origin rpy="1.57075 3.14159 0" xyz="0.0 0.0 0"/>
    <axis xyz="0 0 -1"/>
    <limit effort="100.0" lower="-1.5" upper="0.8" velocity="1.0"/>
  </joint>
  <link name="r_arm_j7_link">
    <visual>
      <geometry>
        <mesh filename="package://smartpal5_description/meshes/visual/Pal5_rightArm_J7.dae"/>
      </geometry>
      <origin rpy="0 0 0" xyz="0 0 0"/>
      <material name="grey"/>
    </visual>
    <collision>
      <geometry>
        <mesh filename="package://smartpal5_description/meshes/collision/Pal5_rightArm_J7.dae"/>
      </geometry>
      <origin rpy="0 0 0" xyz="0 0 0"/>
    </collision>
    <inertial>
      <origin rpy="0 0 0" xyz="0 0 -0.1"/>
      <mass value="0.4"/>
      <inertia ixx="1.0" ixy="0.0" ixz="0.0" iyy="1.0" iyz="0.0" izz="1.0"/>
    </inertial>
  </link>
  <!-- Right Gripper -->
  <joint name="r_gripper_joint" type="fixed">
    <parent link="r_arm_j7_link"/>
    <child link="r_gripper_link"/>
    <origin rpy="3.14159 3.14159 3.14159" xyz="0.056 0 0"/>
    <axis xyz="0 0 1"/>
  </joint>
  <link name="r_gripper_link">
    <visual>
      <geometry>
        <mesh filename="package://smartpal5_description/meshes/visual/Pal5_rightGripper_gripper.dae"/>
      </geometry>
      <origin rpy="0 0 0" xyz="0 0 0"/>
      <material name="grey"/>
    </visual>
    <collision>
      <geometry>
        <mesh filename="package://smartpal5_description/meshes/collision/Pal5_rightGripper_gripper.dae"/>
      </geometry>
      <origin rpy="0 0 0" xyz="0 0 0"/>
    </collision>
    <inertial>
      <origin rpy="0 0 0" xyz="0 0 -0.1"/>
      <mass value="0.6"/>
      <inertia ixx="1.0" ixy="0.0" ixz="0.0" iyy="1.0" iyz="0.0" izz="1.0"/>
    </inertial>
  </link>
  <joint name="r_end_effector_joint" type="fixed">
    <origin rpy="0 0 0" xyz="0.11 0.01 0"/>
    <parent link="r_gripper_link"/>
    <child link="r_end_effector_link"/>
  </joint>
  <link name="r_end_effector_link">
    <visual>
      <origin rpy="0 0 0" xyz="0 0 0"/>
      <geometry>
        <box size="0.001 0.001 0.001"/>
      </geometry>
    </visual>
    <collision>
      <origin rpy="0 0 0" xyz="0 0 0"/>
      <geometry>
        <box size="0.001 0.001 0.001"/>
      </geometry>
    </collision>
  </link>
  <joint name="r_gripper_thumb_joint" type="revolute">
    <parent link="r_gripper_link"/>
    <child link="r_gripper_thumb_link"/>
    <origin rpy="0 0 -1.57075" xyz="0.042 0.027 0.0"/>
    <axis xyz="0 0 -1"/>
    <limit effort="100.0" lower="-1.0122" upper="0.1396" velocity="1.0"/>
  </joint>
  <link name="r_gripper_thumb_link">
    <visual>
      <geometry>
        <mesh filename="package://smartpal5_description/meshes/visual/Pal5_rightGripper_g-thumb.dae"/>
      </geometry>
      <origin rpy="0 0 0" xyz="0 0 0"/>
      <material name="grey"/>
    </visual>
    <collision>
      <geometry>
        <mesh filename="package://smartpal5_description/meshes/collision/Pal5_rightGripper_g-thumb.dae"/>
      </geometry>
      <origin rpy="0 0 0" xyz="0 0 0"/>
    </collision>
    <inertial>
      <origin rpy="0 0 0" xyz="0 0 -0.1"/>
      <mass value="0.4"/>
      <inertia ixx="1.0" ixy="0.0" ixz="0.0" iyy="1.0" iyz="0.0" izz="1.0"/>
    </inertial>
  </link>
  <!-- <xacro:macro name="wheelchair"> -->
  <!-- wheelchair -->
  <link name="wheelchair_x_link"/>
  <joint name="wheelchair_x_joint" type="prismatic">
    <parent link="world_link"/>
    <child link="wheelchair_x_link"/>
    <origin rpy="0 0 0" xyz="0 0 0"/>
    <limit effort="1000.0" lower="0." upper="15." velocity="5.0"/>
  </joint>
  <link name="wheelchair_y_link"/>
  <joint name="wheelchair_y_joint" type="prismatic">
    <parent link="wheelchair_x_link"/>
    <child link="wheelchair_y_link"/>
    <origin rpy="0 0 1.57079633" xyz="0 0 0"/>
    <limit effort="1000.0" lower="0." upper="8." velocity="5.0"/>
  </joint>
  <joint name="wheelchair_yaw_joint" type="continuous">
    <parent link="wheelchair_y_link"/>
    <child link="wheelchair_link"/>
    <origin rpy="0 0 0" xyz="0 0 0"/>
    <axis xyz="0 0 1"/>
  </joint>
  <link name="wheelchair_link">
    <visual>
      <geometry>
        <mesh filename="package://environmental_model/model/wheelchair.dae"/>
      </geometry>
      <origin rpy="0 0 0" xyz="0.0 0.0 0.56"/>
    </visual>
    <collision>
      <geometry>
        <box size="0.6 0.5 1.1"/>
      </geometry>
      <origin rpy="0 0 0" xyz="0.0 0.0 0.56"/>
    </collision>
  </link>
  <!-- </xacro:macro> -->
</robot>

